Workbook

Sheet FS (2)
B3: For the year ended December 31,
B4: (LKR '000 except per share data) | C4: 2017 | D4: 2018 | E4: 2019 | F4: 2020 | G4: 2021 | H4: 2022 | I4: 2023F | J4: 2024F | K4: 2025F | L4: 2026F
B5: INCOME STATEMENT
B6: Gross income | C6: 115605156 | D6: 139657195 | E6: 150741129 | F6: 151966413 | G6: 163675312 | H6: 280386944 | I6: =I7+I10+I13+I14+I15 -> 0 | J6: =J7+J10+J13+J14+J15 -> 0 | K6: =K7+K10+K13+K14+K15 -> 0 | L6: =L7+L10+L13+L14+L15 -> 0
B7: Interest income | C7: 104049102 | D7: 118551239 | E7: 129287743 | F7: 124087713 | G7: 132818178 | H7: 222393079
B8: Less: Interest expense | C8: 64481804 | D8: 72933030 | E8: 80931352 | F8: 73218911 | G8: 66401846 | H8: 137727868
B9: Net interest income | C9: 39567298 | D9: 45618209 | E9: 48356391 | F9: 50868802 | G9: 66416332 | H9: 84665211 | I9: =I7-I8 -> 0 | J9: =J7-J8 -> 0 | K9: =K7-K8 -> 0 | L9: =L7-L8 -> 0
B10: Fee and commission income | C10: 10510800 | D10: 12494090 | E10: 12874966 | F10: 11839689 | G10: 15917337 | H10: 26191530
B11: Less: Fee and commission expense | C11: 1586334 | D11: 1859698 | E11: 2123128 | F11: 2018014 | G11: 3675143 | H11: 6022429
B12: Net fee and commission income | C12: 8924466 | D12: 10634392 | E12: 10751838 | F12: 9821675 | G12: 12242194 | H12: 20169101 | I12: =I10-I11 -> 0 | J12: =J10-J11 -> 0 | K12: =K10-K11 -> 0 | L12: =L10-L11 -> 0
B13: Net gains/(losses) from trading | C13: 233956 | D13: -3033236 | E13: 1360833 | F13: 1878060 | G13: 1936007 | H13: 35297450
B14: Net gains/(losses) from derecognition of financial assets | C14: 91272 | D14: 272004 | E14: 1135711 | F14: 6390197 | G14: 3001574 | H14: 276884
B15: Net other operating income | C15: 720026 | D15: 11373098 | E15: 6081876 | F15: 7770754 | G15: 10002216 | H15: -3771999
B16: Total operating income | C16: 49537018 | D16: 64864467 | E16: 67686649 | F16: 76729488 | G16: 93598323 | H16: 136636647 | I16: =I9+I12+I13+I14+I15 -> 0 | J16: =J9+J12+J13+J14+J15 -> 0 | K16: =K9+K12+K13+K14+K15 -> 0 | L16: =L9+L12+L13+L14+L15 -> 0
B17: Less: Impairment charges and other losses | C17: 989315 | D17: 8833362 | E17: 11331523 | F17: 21419532 | G17: 25139926 | H17: 71924260
B18: Net operating income | C18: 48547703 | D18: 56031105 | E18: 56355126 | F18: 55309956 | G18: 68458397 | H18: 64712387 | I18: =I16-I17 -> 0 | J18: =J16-J17 -> 0 | K18: =K16-K17 -> 0 | L18: =L16-L17 -> 0
B19: Less: Expenses
B20: Personnel expenses | C20: 11338517 | D20: 13289668 | E20: 14408914 | F20: 14992748 | G20: 16799212 | H20: 19788283
B21: Depreciation and amortisation | C21: 1416927 | D21: 1603118 | E21: 2841264 | F21: 3102695 | G21: 3220066 | H21: 3598371
B22: Other operating expenses | C22: 7618993 | D22: 8993958 | E22: 8875316 | F22: 8167170 | G22: 9638461 | H22: 12895587
B23: Total operating expenses | C23: 20374437 | D23: 23886744 | E23: 26125494 | F23: 26262613 | G23: 29657739 | H23: 36282241 | I23: =I20+I21+I22 -> 0 | J23: =J20+J21+J22 -> 0 | K23: =K20+K21+K22 -> 0 | L23: =L20+L21+L22 -> 0
B24: Operating profit before taxes on financial services | C24: 28173266 | D24: 32144361 | E24: 30229632 | F24: 29047343 | G24: 38800658 | H24: 28430146 | I24: =I18-I23 -> 0
B25: Less: Taxes on financial services | C25: 4896620 | D25: 6051861 | E25: 7255728 | F25: 4531381 | G25: 5845230 | H25: 3921381
B26: Operating profit after taxes on financial services | C26: 23276646 | D26: 26092500 | E26: 22973904 | F26: 24515962 | G26: 32955428 | H26: 24508765 | I26: =I24-I25 -> 0 | J26: =J24-J25 -> 0 | K26: =K24-K25 -> 0 | L26: =L24-L25 -> 0
B27: Share of profit/(loss) of associate, net of tax | C27: 3678 | D27: 6048 | E27: 9992 | F27: 3898 | G27: 1896 | H27: -3727
B28: Profit before tax | C28: 23280324 | D28: 26098548 | E28: 22983896 | F28: 24519860 | G28: 32957324 | H28: 24505038 | I28: =I26+I27 -> 0 | J28: =J26+J27 -> 0 | K28: =K26+K27 -> 0 | L28: =L26+L27 -> 0
B29: Less: Income tax expense/(reversal) | C29: 6653817 | D29: 8235717 | E29: 5563500 | F29: 7433063 | G29: 8667036 | H29: 105566
B30: Profit for the year | C30: 16626507 | D30: 17862831 | E30: 17420396 | F30: 17086797 | G30: 24290288 | H30: 24399472 | I30: =I28-I29 -> 0 | J30: =J28-J29 -> 0 | K30: =K28-K29 -> 0 | L30: =L28-L29 -> 0
B31: Profit attributable to: Equity holders of the Bank | C31: 16605963 | D31: 17734706 | E31: 17263259 | F31: 16939950 | G31: 24062469 | H31: 23811914
B32: Non-controlling interest | C32: 20544 | D32: 128125 | E32: 157137 | F32: 146847 | G32: 227819 | H32: 587558
B33: Profit for the year | C33: 16626507 | D33: 17862831 | E33: 17420396 | F33: 17086797 | G33: 24290288 | H33: 24399472 | I33: =I30 -> 0 | J33: =J30 -> 0 | K33: =K30 -> 0 | L33: =L30 -> 0
B34: Earnings per share Basic earnings per ordinary share (Rs.) | C34: 17.05 | D34: 17.55 | E34: 16.41 | F34: 15.7 | G34: 19.41 | H34: 19.21
B35: Diluted earnings per ordinary share (Rs.) | C35: 17.03 | D35: 17.55 | E35: 16.41 | F35: 15.7 | G35: 19.41 | H35: 19.21
B37: OCI
B38: Transfer of FV losses reclassification of debt from FVTOCI to AC | G38: 0 | H38: 26481256
B40: IS check | C40: =IF(C18-C23-C25+C27-C29-C30=0,"OK","FLAG") -> OK | D40: =IF(D18-D23-D25+D27-D29-D30=0,"OK","FLAG") -> OK | E40: =IF(E18-E23-E25+E27-E29-E30=0,"OK","FLAG") -> OK | F40: =IF(F18-F23-F25+F27-F29-F30=0,"OK","FLAG") -> OK | G40: =IF(G18-G23-G25+G27-G29-G30=0,"OK","FLAG") -> OK | H40: =IF(H18-H23-H25+H27-H29-H30=0,"OK","FLAG") -> OK
B42: BALANCE SHEET
B43: Assets
B44: Cash and cash equivalents | C44: 34673424 | D44: 44355962 | E44: 53681118 | F44: 51255030 | G44: 69335379 | H44: 151109490
B45: Balances with Central Banks | C45: 45546349 | D45: 55406535 | E45: 46101232 | F45: 115358732 | G45: 56777465 | H45: 78597120
...

Sheet Cover
B3: COMMERCIAL BANK OF CEYLON PLC
B4: COMB N
B5: COMB X

Sheet FS
L2: l
B3: For the year ended December 31,
B4: (LKR '000 except per share data) | C4: 2017 | D4: 2018 | E4: 2019 | G4: 2020 | H4: 2021 | I4: 2022 | J4: 2023F | K4: 2024F | L4: 2025F | M4: 2026F | O4: Annualised | P4: 9M Sep23 | Q4: 1H2023 | R4: 1H2022
B5: INCOME STATEMENT
B6: Gross income | C6: 115605156 | D6: 139657195 | E6: 150741129 | G6: 151966413 | H6: 163675312 | I6: 280386944 | J6: =J7+J10+J13+J14+J15 -> 3.4870888e+08 | K6: =K7+K10+K13+K14+K15 -> 3.6286483e+08 | L6: =L7+L10+L13+L14+L15 -> 4.1272143e+08 | M6: =M7+M10+M13+M14+M15 -> 4.6464828e+08 | O6: =P6/9*12 -> 3.4128382e+08 | P6: 255962864 | Q6: 167668267 | R6: 119517450 | S6: =Q6*2 -> 335336534
B7: Interest income | C7: 104049102 | D7: 118551239 | E7: 129287743 | G7: 124087713 | H7: 132818178 | I7: 222393079 | J7: =Drivers!I7 -> 3.0585734e+08 | K7: =Drivers!J7 -> 2.9513936e+08 | L7: =Drivers!K7 -> 3.3784948e+08 | M7: =Drivers!L7 -> 3.8175485e+08 | O7: =P7/9*12 -> 2.9942669e+08 | P7: 224570014 | Q7: 150811644 | R7: 88116673 | S7: =Q7*2 -> 301623288
B8: Less: Interest expense | C8: 64481804 | D8: 72933030 | E8: 80931352 | G8: 73218911 | H8: 66401846 | I8: 137727868 | J8: =Drivers!I58 -> 2.2269493e+08 | K8: =Drivers!J58 -> 2.3202049e+08 | L8: =Drivers!K58 -> 2.6615841e+08 | M8: =Drivers!L58 -> 3.0080788e+08 | O8: =P8/9*12 -> 2.18251e+08 | P8: 163688252 | Q8: 113361974 | R8: 47404088 | S8: =Q8*2 -> 226723948
B9: Net interest income | C9: 39567298 | D9: 45618209 | E9: 48356391 | G9: 50868802 | H9: 66416332 | I9: 84665211 | J9: =J7-J8 -> 83162406 | K9: =K7-K8 -> 63118873 | L9: =L7-L8 -> 71691068 | M9: =M7-M8 -> 80946963 | O9: =P9/9*12 -> 81175683 | P9: 60881762 | Q9: 37449670 | R9: 40712585 | S9: =Q9*2 -> 74899340
B10: Fee and commission income | C10: 10510800 | D10: 12494090 | E10: 12874966 | G10: 11839689 | H10: 15917337 | I10: 26191530 | J10: =Drivers!I78 -> 30373717 | K10: =Drivers!J78 -> 35658826 | L10: =Drivers!K78 -> 41280198 | M10: =Drivers!L78 -> 47701081 | O10: =P10/9*12 -> 29379307 | P10: 22034480 | Q10: 14377446 | R10: 11758745 | S10: =Q10*2 -> 28754892
B11: Less: Fee and commission expense | C11: 1586334 | D11: 1859698 | E11: 2123128 | G11: 2018014 | H11: 3675143 | I11: 6022429 | J11: =Drivers!I93 -> 7593429.2 | K11: =Drivers!J93 -> 8201529.9 | L11: =Drivers!K93 -> 9494445.4 | M11: =Drivers!L93 -> 10971249 | O11: =P11/9*12 -> 7766089.3 | P11: 5824567 | Q11: 3786488 | R11: 2881243 | S11: =Q11*2 -> 7572976
B12: Net fee and commission income | C12: 8924466 | D12: 10634392 | E12: 10751838 | G12: 9821675 | H12: 12242194 | I12: 20169101 | J12: =J10-J11 -> 22780287 | K12: =K10-K11 -> 27457296 | L12: =L10-L11 -> 31785752 | M12: =M10-M11 -> 36729832 | O12: =P12/9*12 -> 21613217 | P12: 16209913 | Q12: 10590958 | R12: 8877502 | S12: =Q12*2 -> 21181916
B13: Net gains/(losses) from trading | C13: 233956 | D13: -3033236 | E13: 1360833 | G13: 1878060 | H13: 1936007 | I13: 35297450 | J13: =Drivers!I106 -> -16199576 | K13: =Drivers!J106 -> 1955367.1 | L13: =Drivers!K106 -> 1974920.7 | M13: =Drivers!L106 -> 1994669.9 | O13: =P13/9*12 -> -16199576 | P13: -12149682 | Q13: -15531353 | R13: 32101899 | S13: =Q13*2 -> -31062706
B14: Net gains/(losses) from derecognition of financial assets | C14: 91272 | D14: 272004 | E14: 1135711 | G14: 6390197 | H14: 3001574 | I14: 276884 | J14: =P14/9*12 -> 3517693.3 | K14: =J14*1.05 -> 3693578 | L14: =K14*1.05 -> 3878256.9 | M14: =L14*1.05 -> 4072169.7 | O14: =P14/9*12 -> 3517693.3 | P14: 2638270 | Q14: 924510 | R14: 64262 | S14: =Q14*2 -> 1849020
B15: Net other operating income | C15: 720026 | D15: 11373098 | E15: 6081876 | G15: 7770754 | H15: 10002216 | I15: -3771999 | J15: =Drivers!I123 -> 25159709 | K15: =Drivers!J123 -> 26417695 | L15: =Drivers!K123 -> 27738580 | M15: =Drivers!L123 -> 29125509 | O15: =P15/9*12 -> 25159709 | P15: 18869782 | Q15: 17086020 | R15: -12524129 | S15: =Q15*2 -> 34172040
B16: Total operating income | C16: 49537018 | D16: 64864467 | E16: 67686649 | G16: 76729488 | H16: 93598323 | I16: 136636647 | J16: =J9+J12+J13+J14+J15 -> 1.1842052e+08 | K16: =K9+K12+K13+K14+K15 -> 1.2264281e+08 | L16: =L9+L12+L13+L14+L15 -> 1.3706858e+08 | M16: =M9+M12+M13+M14+M15 -> 1.5286914e+08 | O16: =P16/9*12 -> 1.1526673e+08 | P16: 86450045 | Q16: 50519805 | R16: 69232119 | S16: =Q16*2 -> 101039610
B17: Less: Impairment charges and other losses | C17: 989315 | D17: 8833362 | E17: 11331523 | G17: 21419532 | H17: 25139926 | I17: 71924260 | J17: =Drivers!I138 -> 35328926 | K17: =Drivers!J138 -> 30095011 | L17: =Drivers!K138 -> 34609262 | M17: =Drivers!L138 -> 39800652 | O17: =P17/9*12 -> 34376147 | P17: 25782110 | Q17: 13210963 | R17: 35218619 | S17: =Q17*2 -> 26421926
B18: Net operating income | C18: 48547703 | D18: 56031105 | E18: 56355126 | G18: 55309956 | H18: 68458397 | I18: 64712387 | J18: =J16-J17 -> 83091594 | K18: =K16-K17 -> 92547798 | L18: =L16-L17 -> 1.0245931e+08 | M18: =M16-M17 -> 1.1306849e+08 | O18: =P18/9*12 -> 80890580 | P18: 60667935 | Q18: 37308842 | R18: 34013500 | S18: =Q18*2 -> 74617684
B19: Less: Expenses | O19: =P19/9*12 -> 0 | S19: =Q19*2 -> 0
B20: Personnel expenses | C20: 11338517 | D20: 13289668 | E20: 14408914 | G20: 14992748 | H20: 16799212 | I20: 19788283 | J20: =Drivers!I155 -> 21767111 | K20: =Drivers!J155 -> 23943822 | L20: =Drivers!K155 -> 26338205 | M20: =Drivers!L155 -> 28972025 | O20: =P20/9*12 -> 22412377 | P20: 16809283 | Q20: 11296515 | R20: 9584347 | S20: =Q20*2 -> 22593030
B21: Depreciation and amortisation | C21: 1416927 | D21: 1603118 | E21: 2841264 | G21: 3102695 | H21: 3220066 | I21: 3598371 | J21: =Drivers!I172 -> 4116991 | K21: =Drivers!J172 -> 4240227.2 | L21: =Drivers!K172 -> 4381833.5 | M21: =Drivers!L172 -> 4529601.5 | O21: =P21/9*12 -> 4106025.3 | P21: 3079519 | Q21: 2084338 | R21: 1724022 | S21: =Q21*2 -> 4168676
B22: Other operating expenses | C22: 7618993 | D22: 8993958 | E22: 8875316 | G22: 8167170 | H22: 9638461 | I22: 12895587 | J22: =Drivers!I184 -> 16764263 | K22: =Drivers!J184 -> 20117116 | L22: =Drivers!K184 -> 24140539 | M22: =Drivers!L184 -> 28968647 | O22: =P22/9*12 -> 16116592 | P22: 12087444 | Q22: 7903941 | R22: 6723078 | S22: =Q22*2 -> 15807882
B23: Total operating expenses | C23: 20374437 | D23: 23886744 | E23: 26125494 | G23: 26262613 | H23: 29657739 | I23: 36282241 | J23: =J20+J21+J22 -> 42648365 | K23: =K20+K21+K22 -> 48301165 | L23: =L20+L21+L22 -> 54860577 | M23: =M20+M21+M22 -> 62470273 | O23: =P23/9*12 -> 42634995 | P23: 31976246 | Q23: 21284794 | R23: 18031447 | S23: =Q23*2 -> 42569588
B24: Operating profit before taxes on financial services | C24: 28173266 | D24: 32144361 | E24: 30229632 | G24: 29047343 | H24: 38800658 | I24: 28430146 | J24: =J18-J23 -> 40443229 | K24: =K18-K23 -> 44246633 | L24: =L18-L23 -> 47598738 | M24: =M18-M23 -> 50598219 | O24: =P24/9*12 -> 38255585 | P24: 28691689 | Q24: 16024048 | R24: 15982053 | S24: =Q24*2 -> 32048096
B25: Less: Taxes on financial services | C25: 4896620 | D25: 6051861 | E25: 7255728 | G25: 4531381 | H25: 5845230 | I25: 3921381 | J25: =Drivers!I196 -> 4893717.4 | K25: =Drivers!J196 -> 5902787.2 | L25: =Drivers!K196 -> 6756989.5 | M25: =Drivers!L196 -> 7635097 | O25: =P25/9*12 -> 4886169.3 | P25: 3664627 | Q25: 1933968 | R25: 2602781 | S25: =Q25*2 -> 3867936
B26: Operating profit after taxes on financial services | C26: 23276646 | D26: 26092500 | E26: 22973904 | G26: 24515962 | H26: 32955428 | I26: 24508765 | J26: =J24-J25 -> 35549511 | K26: =K24-K25 -> 38343846 | L26: =L24-L25 -> 40841748 | M26: =M24-M25 -> 42963122 | O26: =P26/9*12 -> 33369416 | P26: 25027062 | Q26: 14090080 | R26: 13379272 | S26: =Q26*2 -> 28180160
B27: Share of profit/(loss) of associate, net of tax | C27: 3678 | D27: 6048 | E27: 9992 | G27: 3898 | H27: 1896 | I27: -3727 | J27: =P27/9*12 -> 5197.3333 | K27: =J27*1.01 -> 5249.3067 | L27: =K27*1.01 -> 5301.7997 | M27: =L27*1.01 -> 5354.8177 | O27: =P27/9*12 -> 5197.3333 | P27: 3898 | Q27: 2352 | R27: -3476 | S27: =Q27*2 -> 4704
B28: Profit before tax | C28: 23280324 | D28: 26098548 | E28: 22983896 | G28: 24519860 | H28: 32957324 | I28: 24505038 | J28: =J26+J27 -> 35554709 | K28: =K26+K27 -> 38349095 | L28: =L26+L27 -> 40847050 | M28: =M26+M27 -> 42968476 | O28: =P28/9*12 -> 33374613 | P28: 25030960 | Q28: 14092432 | R28: 13375796 | S28: =Q28*2 -> 28184864
B29: Less: Income tax expense/(reversal) | C29: 6653817 | D29: 8235717 | E29: 5563500 | G29: 7433063 | H29: 8667036 | I29: 105566 | J29: =Drivers!I206 -> 14932978 | K29: =Drivers!J206 -> 11504728 | L29: =Drivers!K206 -> 12254115 | M29: =Drivers!L206 -> 12890543 | O29: =P29/9*12 -> 13689807 | P29: 10267355 | Q29: 5801958 | R29: 4198046 | S29: =Q29*2 -> 11603916
B30: Profit for the year | C30: 16626507 | D30: 17862831 | E30: 17420396 | G30: 17086797 | H30: 24290288 | I30: 24399472 | J30: =J28-J29 -> 20621731 | K30: =K28-K29 -> 26844366 | L30: =L28-L29 -> 28592935 | M30: =M28-M29 -> 30077933 | O30: =P30/9*12 -> 19684807 | P30: 14763605 | Q30: 8290474 | R30: 9177750 | S30: =Q30*2 -> 16580948
B31: Profit attributable to: Equity holders of the Bank | C31: 16605963 | D31: 17734706 | E31: 17263259 | G31: 16939950 | H31: 24062469 | I31: 23811914 | J31: =J30*0.96 -> 19796862 | K31: =K30*0.96 -> 25770592 | L31: =L30*0.96 -> 27449218 | M31: =M30*0.96 -> 28874816 | O31: =P31/9*12 -> 18933237 | P31: 14199928 | Q31: 7966526 | R31: 8940996
B32: Non-controlling interest | C32: 20544 | D32: 128125 | E32: 157137 | G32: 146847 | H32: 227819 | I32: 587558 | J32: =J30*0.04 -> 824869.24 | K32: =K30*0.04 -> 1073774.7 | L32: =L30*0.04 -> 1143717.4 | M32: =M30*0.04 -> 1203117.3 | O32: =P32/9*12 -> 751569.33 | P32: 563677 | Q32: 323948 | R32: 236754
B33: Profit for the year | C33: 16626507 | D33: 17862831 | E33: 17420396 | G33: 17086797 | H33: 24290288 | I33: 24399472 | J33: =J30 -> 20621731 | K33: =K30 -> 26844366 | L33: =L30 -> 28592935 | M33: =M30 -> 30077933 | O33: =P33/9*12 -> 19684807 | P33: =P30 -> 14763605 | Q33: =Q30 -> 8290474 | R33: =R30 -> 9177750
B34: Earnings per share Basic earnings per ordinary share (Rs.) | C34: 17.05 | D34: 17.55 | E34: 16.41 | G34: 15.7 | H34: 19.41 | I34: 19.21 | J34: =J31*1000/Drivers!I586 -> 15.064716 | K34: =K31*1000/Drivers!J586 -> 19.610515 | L34: =L31*1000/Drivers!K586 -> 20.88789 | M34: =M31*1000/Drivers!L586 -> 21.97272 | P34: 10.81 | Q34: 6.07 | R34: 7.21
B35: Diluted earnings per ordinary share (Rs.) | C35: 17.03 | D35: 17.55 | E35: 16.41 | G35: 15.7 | H35: 19.41 | I35: 19.21 | P35: 10.81 | Q35: 6.07 | R35: 7.21
B36: Diviend per share | D36: 6.5 | E36: 6.5 | G36: 6.5 | H36: 7.5 | I36: 4.5 | J36: =#REF! -> #REF! | K36: =-Drivers!J619*1000/Drivers!J586 -> 6.8636802 | L36: =-Drivers!K619*1000/Drivers!K586 -> 7.3107615 | M36: =-Drivers!L619*1000/Drivers!L586 -> 7.6904522
B38: OCI
B39: Transfer of FV losses reclassification of debt from FVTOCI to AC | H39: 0 | I39: 26481256
B41: IS check | C41: =IF(C18-C23-C25+C27-C29-C30+C31+C32-C33=0,"OK","FLAG") -> OK | D41: =IF(D18-D23-D25+D27-D29-D30+D31+D32-D33=0,"OK","FLAG") -> OK | E41: =IF(E18-E23-E25+E27-E29-E30+E31+E32-E33=0,"OK","FLAG") -> OK | G41: =IF(G18-G23-G25+G27-G29-G30+G31+G32-G33=0,"OK","FLAG") -> OK | H41: =IF(H18-H23-H25+H27-H29-H30+H31+H32-H33=0,"OK","FLAG") -> OK | I41: =IF(I18-I23-I25+I27-I29-I30+I31+I32-I33=0,"OK","FLAG") -> OK | J41: =J18-J23-J25+J27-J29-J30+J31+J32-J33 -> 0 | K41: =K18-K23-K25+K27-K29-K30+K31+K32-K33 -> 0 | L41: =L18-L23-L25+L27-L29-L30+L31+L32-L33 -> 0 | M41: =M18-M23-M25+M27-M29-M30+M31+M32-M33 -> 0 | Q41: =IF(Q18-Q23-Q25+Q27-Q29-Q30=0,"OK","FLAG") -> OK | R41: =IF(R18-R23-R25+R27-R29-R30=0,"OK","FLAG") -> OK
B43: BALANCE SHEET
B44: Assets
...

Sheet Drivers
B3: For the year ended December 31, | N3: Annualised | P3: Period | Q3: Quarter
B4: (LKR '000 except per share data) | C4: 2017 | D4: 2018 | E4: 2019 | F4: 2020 | G4: 2021 | H4: 2022 | I4: 2023F | J4: 2024F | K4: 2025F | L4: 2026F | N4: 45192 | O4: 45100 | P4: 45078
B5: INCOME STATEMENT
B7: Interest income | C7: 104049102 | D7: 118551239 | E7: 129287743 | F7: 124087713 | G7: 132818178 | H7: 222393079 | I7: =I13+SUM(I14:I19) -> 3.0585734e+08 | J7: =J13+SUM(J14:J19) -> 2.9513936e+08 | K7: =K13+SUM(K14:K19) -> 3.3784948e+08 | L7: =L13+SUM(L14:L19) -> 3.8175485e+08 | N7: =FS!P7/9*12 -> 2.9942669e+08 | P7: 150811644 | Q7: 88116673 | R7: =P7*2 -> 301623288
B9: Cash and cash equivalents | C9: 362695 | D9: 411412 | E9: 1290697 | F9: 1053757 | G9: 447742 | H9: 945450 | I9: =FS!I45*Drivers!I55 -> 2055089.1 | J9: =FS!J45*Drivers!J55 -> 1440462 | K9: =FS!K45*Drivers!K55 -> 1491785.1 | L9: =FS!L45*Drivers!L55 -> 2163539.6
B10: Balances with Central Banks | C10: 4400 | D10: 26734 | E10: 62572 | F10: 1175509 | G10: 1299948 | H10: 815979
B11: Placements with Banks | C11: 215909 | D11: 529738 | E11: 931571 | F11: 777425 | G11: 778021 | H11: 1685996 | I11: =I252*I28 -> 1348796.8 | J11: =J252*J28 -> 1416236.6 | K11: =K252*K28 -> 1487048.5 | L11: =L252*L28 -> 1561400.9
B12: Securities purchased under resale agreements | C12: 139153 | D12: 508616 | E12: 1906902 | F12: 836773 | G12: 375398 | H12: 1133583 | I12: =I264*I29 -> 453433.2 | J12: =J264*J29 -> 476104.86 | K12: =K264*K29 -> 499910.1 | L12: =L264*L29 -> 524905.61
B13: Financial assets recognized through profit or loss | C13: 469012 | D13: 323335 | E13: 474478 | F13: 1831327 | G13: 1101385 | H13: 1516691 | I13: =SUM(I9:I12) -> 3857319.1 | J13: =SUM(J9:J12) -> 3332803.5 | K13: =SUM(K9:K12) -> 3478743.7 | L13: =SUM(L9:L12) -> 4249846.1
B14: Derivatives | C14: 24111 | D14: 56173 | E14: 67453 | F14: 34902 | G14: 167377 | H14: 237438 | I14: =I266*I31 -> 166206.6 | J14: =J266*J31 -> 174516.93 | K14: =K266*K31 -> 183242.78 | L14: =L266*L31 -> 192404.92
B15: Other financial instruments | C15: 444901 | D15: 267162 | E15: 407025 | F15: 1796425 | G15: 934008 | H15: 1279253 | I15: =I271*I32 -> 4946643.7 | J15: =J271*J32 -> 7798003.1 | K15: =K271*K32 -> 8577803.4 | L15: =L271*L32 -> 9435583.8
B16: Financial assets at amortized cost - loans and advances to other customers | C16: 78132371 | D16: 95081154 | E16: 100444369 | F16: 84257196 | G16: 79654575 | H16: 144253496 | I16: =I33*I305 -> 2.028142e+08 | J16: =J33*J305 -> 1.8785541e+08 | K16: =K33*K305 -> 2.1976882e+08 | L16: =L33*L305 -> 2.5273414e+08
B17: Financial assets at amortized cost - debt and other financial instruments | C17: 8512118 | D17: 6828671 | E17: 7819563 | F17: 13194851 | G17: 25951467 | H17: 51750895 | I17: =I50*I341 -> 48193316 | J17: =J50*J341 -> 45412106 | K17: =K50*K341 -> 50127260 | L17: =L50*L341 -> 53757016
B18: Financial assets measured at fair value through other comprehensive income | C18: 15349974 | D18: 14478042 | E18: 15091368 | F18: 18053545 | G18: 22034788 | H18: 18995711 | I18: =I52*I384 -> 44543209 | J18: =J52*J384 -> 48997530 | K18: =K52*K384 -> 53897283 | L18: =L52*L384 -> 59287011
B19: Interest accrued on impaired loans and advances to other customers | C19: 861057 | D19: 360876 | E19: 1258339 | F19: 2895955 | G19: 1174854 | H19: 1295278 | I19: =I53*I289 -> 1336443.5 | J19: =J53*J289 -> 1568988.3 | K19: =K53*K289 -> 1816328.7 | L19: =L53*L289 -> 2098847.6
C20: 2413 | D20: 2661 | E20: 7884 | F20: 11375 | G20: 0 | H20: 0
B22: Check | C22: =SUM(C9:C13)+C16+C17+C18+C19+C20-C7 -> 0 | D22: =SUM(D9:D13)+D16+D17+D18+D19+D20-D7 -> 0 | E22: =SUM(E9:E13)+E16+E17+E18+E19+E20-E7 -> 0 | F22: =SUM(F9:F13)+F16+F17+F18+F19+F20-F7 -> 0 | G22: =SUM(G9:G13)+G16+G17+G18+G19+G20-G7 -> 0 | H22: =SUM(H9:H13)+H16+H17+H18+H19+H20-H7 -> 0
B24: Interest rate
B26: Cash and cash equivalents | C26: =C9/FS!C45 -> 0.010460317 | D26: =D9/FS!D45 -> 0.0092752356 | E26: =E9/FS!E45 -> 0.02404378 | F26: =F9/FS!G45 -> 0.020559094 | G26: =G9/FS!H45 -> 0.0064576268 | H26: =H9/FS!I45 -> 0.0062567215 | I26: 0.0062567215 | J26: 0.0062567215 | K26: 0.0062567215 | L26: 0.0062567215
B27: Balances with Central Banks | C27: =C10/FS!C46 -> 9.6604889e-05 | D27: =D10/FS!D46 -> 0.00048250626 | E27: =E10/FS!E46 -> 0.0013572739 | F27: =F10/FS!G46 -> 0.010190031 | G27: =G10/FS!H46 -> 0.022895492 | H27: =H10/FS!I46 -> 0.010381793 | I27: 0.010381793 | J27: 0.010381793 | K27: 0.010381793 | L27: 0.010381793
B28: Placements with Banks | C28: =C11/FS!C47 -> 0.012244411 | D28: =D11/FS!D47 -> 0.026621987 | E28: =E11/FS!E47 -> 0.037406768 | F28: =F11/FS!G47 -> 0.047340841 | G28: =G11/FS!H47 -> 0.062248109 | H28: =H11/FS!I47 -> 0.017547299 | I28: 0.017547299 | J28: 0.017547299 | K28: 0.017547299 | L28: 0.017547299
B29: Securities purchased under resale agreements | C29: =C12/FS!C48 -> #DIV/0! | D29: =D12/FS!D48 -> 0.053462486 | E29: =E12/FS!E48 -> 0.14503876 | F29: =F12/FS!G48 -> #DIV/0! | G29: =G12/FS!H48 -> 0.12511223 | H29: =H12/FS!I48 -> 0.74710145 | I29: 0.74710145 | J29: 0.74710145 | K29: 0.74710145 | L29: 0.74710145
B30: Financial assets recognized through profit or loss
B31: Derivatives | C31: =C14/FS!C49 -> 0.010327962 | D31: =D14/FS!D49 -> 0.0071015512 | E31: =E14/FS!E49 -> 0.036840901 | F31: =F14/FS!G49 -> 0.013236915 | G31: =G14/FS!H49 -> 0.051578062 | H31: =H14/FS!I49 -> 0.028452416 | I31: 0.028452416 | J31: 0.028452416 | K31: 0.028452416 | L31: 0.028452416
B32: Other financial instruments | C32: =C15/C271 -> 0.1008637 | D32: =D15/D271 -> 0.048397449 | E32: =E15/E271 -> 0.018959585 | F32: =F15/F271 -> 0.051050071 | G32: =G15/G271 -> 0.039853349 | H32: =H15/H271 -> 0.051431274 | I32: 0.05 | J32: 0.05 | K32: 0.05 | L32: 0.05
B33: Financial assets at amortized cost - loans and advances to other customers | C33: =C16/FS!C52 -> 0.1052367 | D33: =D16/FS!D52 -> 0.10958949 | E33: =E16/FS!E52 -> 0.11236402 | F33: =F16/FS!G52 -> 0.09260771 | G33: =G16/FS!H52 -> 0.07736578 | H33: =H16/FS!I52 -> 0.12484157 | I33: 0.155 | J33: 0.12484157 | K33: 0.127 | L33: 0.127
B34: Overdrafts | H34: 0.28 | I34: 0.28 | J34: 0.28 | K34: 0.28 | L34: 0.28
B35: Trade finance | H35: 0.155 | I35: 0.155 | J35: 0.155 | K35: 0.155 | L35: 0.155
B36: Lease/hire purchase receivable | H36: 0.16 | I36: 0.16 | J36: 0.16 | K36: 0.16 | L36: 0.16
B37: Credit cards | H37: 0.28 | I37: 0.28 | J37: 0.28 | K37: 0.28 | L37: 0.28
B38: Pawning
B39: Staff loans
B40: Housing loans | H40: 0.15 | I40: 0.15 | J40: 0.15 | K40: 0.15 | L40: 0.15
B41: Personal loans
B42: Term loans
B43: Short term
B44: Long term | H44: =H47+2% -> 0.16 | I44: 0.16 | J44: 0.16 | K44: 0.16 | L44: 0.16
B45: Bills of exchange
B47: Average AWPLR throughout the year | H47: 0.14 | I47: 0.14 | J47: 0.14 | K47: 0.14 | L47: 0.14
B50: Financial assets at amortized cost - debt and other financial instruments | C50: =C17/FS!C53 -> 0.072088775 | D50: =D17/FS!D53 -> 0.076490797 | E50: =E17/FS!E53 -> 0.073039739 | F50: =F17/FS!G53 -> 0.043682949 | G50: =G17/FS!H53 -> 0.067338091 | H50: =H17/FS!I53 -> 0.067945748 | I50: 0.067945748 | J50: 0.067945748 | K50: 0.067945748 | L50: 0.067945748
...

Sheet Ratios
C2: =FS!C4 -> 2017 | D2: =FS!D4 -> 2018 | E2: =FS!E4 -> 2019 | F2: =FS!G4 -> 2020 | G2: =FS!H4 -> 2021 | H2: =FS!I4 -> 2022 | I2: =FS!J4 -> 2023F | J2: =FS!K4 -> 2024F | K2: =FS!L4 -> 2025F | L2: =FS!M4 -> 2026F
B3: Avg. yield on interest earning assets | C3: =FS!C7/(FS!C49+FS!C50+FS!C51+FS!C52+FS!C53+FS!C54) -> 0.10172748 | D3: =FS!D7/(FS!D49+FS!D50+FS!D51+FS!D52+FS!D53+FS!D54) -> 0.10328201 | E3: =FS!E7/(FS!E49+FS!E50+FS!E51+FS!E52+FS!E53+FS!E54) -> 0.1057257 | F3: =FS!G7/(FS!G49+FS!G50+FS!G51+FS!G52+FS!G53+FS!G54) -> 0.081144905 | G3: =FS!H7/(FS!H49+FS!H50+FS!H51+FS!H52+FS!H53+FS!H54) -> 0.074717288 | H3: =FS!I7/(FS!I49+FS!I50+FS!I51+FS!I52+FS!I53+FS!I54) -> 0.10748751 | I3: =FS!J7/(FS!J49+FS!J50+FS!J51+FS!J52+FS!J53+FS!J54) -> 0.13149674 | J3: =FS!K7/(FS!K49+FS!K50+FS!K51+FS!K52+FS!K53+FS!K54) -> 0.1142421 | K3: =FS!L7/(FS!L49+FS!L50+FS!L51+FS!L52+FS!L53+FS!L54) -> 0.11545382 | L3: =FS!M7/(FS!M49+FS!M50+FS!M51+FS!M52+FS!M53+FS!M54) -> 0.11603704
B4: Avg. cost on interest bearing funds | C4: =FS!C8/(FS!C64+FS!C65+FS!C66+FS!C67+FS!C68) -> 0.064837643 | D4: =FS!D8/(FS!D64+FS!D65+FS!D66+FS!D67+FS!D68) -> 0.064595781 | E4: =FS!E8/(FS!E64+FS!E65+FS!E66+FS!E67+FS!E68) -> 0.067518664 | F4: =FS!G8/(FS!G64+FS!G65+FS!G66+FS!G67+FS!G68) -> 0.048096509 | G4: =FS!H8/(FS!H64+FS!H65+FS!H66+FS!H67+FS!H68) -> 0.038326172 | H4: =FS!I8/(FS!I64+FS!I65+FS!I66+FS!I67+FS!I68) -> 0.063778484 | I4: =FS!J8/(FS!J64+FS!J65+FS!J66+FS!J67+FS!J68) -> 0.095531498 | J4: =FS!K8/(FS!K64+FS!K65+FS!K66+FS!K67+FS!K68) -> 0.090014943 | K4: =FS!L8/(FS!L64+FS!L65+FS!L66+FS!L67+FS!L68) -> 0.090526292 | L4: =FS!M8/(FS!M64+FS!M65+FS!M66+FS!M67+FS!M68) -> 0.091290321
B5: Net interest margin | C5: =FS!C9/(FS!C49+FS!C50+FS!C51+FS!C52+FS!C53+FS!C54) -> 0.038684441 | D5: =FS!D9/(FS!D49+FS!D50+FS!D51+FS!D52+FS!D53+FS!D54) -> 0.039742648 | E5: =FS!E9/(FS!E49+FS!E50+FS!E51+FS!E52+FS!E53+FS!E54) -> 0.039543682 | F5: =FS!G9/(FS!G49+FS!G50+FS!G51+FS!G52+FS!G53+FS!G54) -> 0.033264729 | G5: =FS!H9/(FS!H49+FS!H50+FS!H51+FS!H52+FS!H53+FS!H54) -> 0.037362719 | H5: =FS!I9/(FS!I49+FS!I50+FS!I51+FS!I52+FS!I53+FS!I54) -> 0.040920576 | I5: =FS!J9/(FS!J49+FS!J50+FS!J51+FS!J52+FS!J53+FS!J54) -> 0.035753876 | J5: =FS!K9/(FS!K49+FS!K50+FS!K51+FS!K52+FS!K53+FS!K54) -> 0.024431959 | K5: =FS!L9/(FS!L49+FS!L50+FS!L51+FS!L52+FS!L53+FS!L54) -> 0.024499099 | L5: =FS!M9/(FS!M49+FS!M50+FS!M51+FS!M52+FS!M53+FS!M54) -> 0.024604392
B6: Interest rate spread | C6: =C3-C4 -> 0.036889834 | D6: =D3-D4 -> 0.038686225 | E6: =E3-E4 -> 0.038207039 | F6: =F3-F4 -> 0.033048396 | G6: =G3-G4 -> 0.036391117 | H6: =H3-H4 -> 0.043709029 | I6: =I3-I4 -> 0.035965245 | J6: =J3-J4 -> 0.024227159 | ... L6: =L3-L4 -> 0.024746718
B7: Cost to income (operating) | C7: =FS!C23/FS!C16 -> 0.4112972 | D7: =FS!D23/FS!D16 -> 0.36825623 | E7: =FS!E23/FS!E16 -> 0.38597706 | F7: =FS!G23/FS!G16 -> 0.34227536 | G7: =FS!H23/FS!H16 -> 0.31686186 | H7: =FS!I23/FS!I16 -> 0.26553814 | I7: =FS!J23/FS!J16 -> 0.36014337 | J7: =FS!K23/FS!K16 -> 0.3938361 | K7: =FS!L23/FS!L16 -> 0.40024182 | L7: =FS!M23/FS!M16 -> 0.40865195
B8: Cost to income (with impairments) | C8: =(FS!C23+FS!C17)/FS!C6 -> 0.1847993 | D8: =(FS!D23+FS!D17)/FS!D6 -> 0.23428872 | E8: =(FS!E23+FS!E17)/FS!E6 -> 0.24848571 | F8: =(FS!G23+FS!G17)/FS!G6 -> 0.31376765 | G8: =(FS!H23+FS!H17)/FS!H6 -> 0.33479493 | H8: =(FS!I23+FS!I17)/FS!I6 -> 0.38591847 | I8: =(FS!J23/FS!J6) -> 0.12230364 | J8: =(FS!K23/FS!K6) -> 0.13311063 | K8: =(FS!L23/FS!L6) -> 0.13292398 | L8: =(FS!M23/FS!M6) -> 0.13444637
B9: Impairments/ Gross loans | C9: =Drivers!C315/Drivers!C311 -> 0.023682969 | D9: =Drivers!D315/Drivers!D311 -> 0.033792109 | E9: =Drivers!E315/Drivers!E311 -> 0.039557968 | F9: =Drivers!F315/Drivers!F311 -> 0.054093105 | G9: =Drivers!G315/Drivers!G311 -> 0.059681216 | H9: =Drivers!H315/Drivers!H311 -> 0.07276509 | I9: =Drivers!I315/Drivers!I311 -> 0.07148 | J9: =Drivers!J315/Drivers!J311 -> 0.0521 | ... L9: =Drivers!L315/Drivers!L311 -> 0.0412
B10: Net margin | C10: =FS!C30/FS!C6 -> 0.1438215 | D10: =FS!D30/FS!D6 -> 0.12790484 | E10: =FS!E30/FS!E6 -> 0.11556498 | F10: =FS!G30/FS!G6 -> 0.11243798 | G10: =FS!H30/FS!H6 -> 0.14840533 | H10: =FS!I30/FS!I6 -> 0.087020714 | I10: =FS!J30/FS!J6 -> 0.059137383 | J10: =FS!K30/FS!K6 -> 0.073978971 | K10: =FS!L30/FS!L6 -> 0.069279017 | L10: =FS!M30/FS!M6 -> 0.064732691
B11: ROE | C11: =FS!C30/FS!C82 -> 0.15272352 | D11: =FS!D30/FS!D82 -> 0.14812024 | E11: =FS!E30/FS!E82 -> 0.12807845 | F11: =FS!G30/FS!G82 -> 0.106163 | G11: =FS!H30/FS!H82 -> 0.14326114 | H11: =FS!I30/FS!I82 -> 0.11456626 | I11: =FS!J30/FS!J82 -> 0.087940259 | J11: =FS!K30/FS!K82 -> 0.10323137 | K11: =FS!L30/FS!L82 -> 0.1004223 | L11: =FS!M30/FS!M82 -> 0.096883779
B12: ROA | C12: =FS!C30/FS!C62 -> 0.014385023 | D12: =FS!D30/FS!D62 -> 0.013533348 | E12: =FS!E30/FS!E62 -> 0.012364174 | F12: =FS!G30/FS!G62 -> 0.0096946578 | G12: =FS!H30/FS!H62 -> 0.01224623 | H12: =FS!I30/FS!I62 -> 0.0097615306 | I12: =FS!J30/FS!J62 -> 0.0077457677 | J12: =FS!K30/FS!K62 -> 0.009090326 | K12: =FS!L30/FS!L62 -> 0.0084873126 | L12: =FS!M30/FS!M62 -> 0.0079878194
B13: Equity/ total assets | C13: =FS!C82/FS!C62 -> 0.094189964 | D13: =FS!D82/FS!D62 -> 0.09136731 | E13: =FS!E82/FS!E62 -> 0.096535943 | F13: =FS!G82/FS!G62 -> 0.091318616 | G13: =FS!H82/FS!H62 -> 0.085481868 | H13: =FS!I82/FS!I62 -> 0.085204233 | I13: =FS!J82/FS!J62 -> 0.088079883 | J13: =FS!K82/FS!K62 -> 0.088057786 | K13: =FS!L82/FS!L62 -> 0.084516214 | L13: =FS!M82/FS!M62 -> 0.082447439
B14: Deposits / total assets | C14: =FS!C67/FS!C62 -> 0.7416981 | D14: =FS!D67/FS!D62 -> 0.75336136 | E14: =FS!E67/FS!E62 -> 0.75871332 | F14: =FS!G67/FS!G62 -> 0.72999671 | G14: =FS!H67/FS!H62 -> 0.74244872 | H14: =FS!I67/FS!I62 -> 0.79123865 | I14: =FS!J67/FS!J62 -> 0.81094232 | J14: =FS!K67/FS!K62 -> 0.80000087 | K14: =FS!L67/FS!L62 -> 0.79616944 | L14: =FS!M67/FS!M62 -> 0.79274167
B15: Cash / total assets | C15: =FS!C45/FS!C62 -> 0.029998966 | D15: =FS!D45/FS!D62 -> 0.033605236 | E15: =FS!E45/FS!E62 -> 0.038100321 | F15: =FS!G45/FS!G62 -> 0.029080932 | G15: =FS!H45/FS!H62 -> 0.034956233 | H15: =FS!I45/FS!I62 -> 0.060454583 | I15: =FS!J45/FS!J62 -> 0.039783431 | J15: =FS!K45/FS!K62 -> 0.037144427 | K15: =FS!L45/FS!L62 -> 0.047221241 | L15: =FS!M45/FS!M62 -> 0.044651353
B16: Gross income per employee | C16: =FS!C6/FS!C87 -> 23204.568 | D16: =FS!D6/FS!D87 -> 27781.419 | E16: =FS!E6/FS!E87 -> 29778.967 | F16: =FS!G6/FS!G87 -> 30050.705 | G16: =FS!H6/FS!H87 -> 32270.369 | H16: =FS!I6/FS!I87 -> 54752.381 | I16: =FS!J6/FS!J87 -> 67419.707 | J16: =FS!K6/FS!K87 -> 69462.011 | K16: =FS!L6/FS!L87 -> 78223.659 | L16: =FS!M6/FS!M87 -> 87193.49
B17: Dividend payout | F17: =FS!G36/FS!G34 -> 0.41401274 | G17: =FS!H36/FS!H34 -> 0.38639876 | H17: =FS!I36/FS!I34 -> 0.23425299 | I17: =FS!J36/FS!J34 -> #REF! | J17: =FS!K36/FS!K34 -> 0.35 | K17: =FS!L36/FS!L34 -> 0.35 | L17: =FS!M36/FS!M34 -> 0.35
B20: Gross income per service centre | C20: =FS!C6/FS!C88 -> 412875.56 | D20: =FS!D6/FS!D88 -> 490025.25 | E20: =FS!E6/FS!E88 -> 525230.41 | F20: =FS!G6/FS!G88 -> 529499.7 | G20: =FS!H6/FS!H88 -> 570297.25 | H20: =FS!I6/FS!I88 -> 970197.04 | I20: =FS!J6/FS!J88 -> 1200602.1 | J20: =FS!K6/FS!K88 -> 1243125.3 | K20: =FS!L6/FS!L88 -> 1406892.8 | L20: =FS!M6/FS!M88 -> 1576021.9
B22: Net interest spread | F22: =F3-F4 -> 0.033048396 | G22: =G3-G4 -> 0.036391117 | H22: =H3-H4 -> 0.043709029 | I22: =I3-I4 -> 0.035965245 | J22: =J3-J4 -> 0.024227159 | K22: =K3-K4 -> 0.024927528 | L22: =L3-L4 -> 0.024746718

Sheet Quarterly
C1: For the quarter ended
C2: 45192 | D2: 45078 | E2: 44986 | F2: 44896 | G2: 44805 | H2: 44713 | I2: 44621 | J2: 44531
B3: Gross income | C3: 88294597 | D3: 83519041 | E3: 84149226 | F3: 84813856 | G3: 76055638 | H3: 64944217 | I3: 54573233 | J3: 43625180 | K3: =E3+D3+C3+C3 -> 344257461
B4: Interest income | C4: 73758370 | D4: 74872632 | E4: 75939012 | F4: 72136429 | G4: 62139977 | H4: 50269825 | I4: 37846848 | J4: 36591673 | K4: =E4+D4+C4+C4 -> 298328384
B5: Less : Interest expense | C5: 50326278 | D5: 56398189 | E5: 56963785 | F5: 50285038 | G5: 40038742 | H5: 28380265 | I5: 19023823 | J5: 17708621 | K5: =E5+D5+C5+C5 -> 214014530
B6: Net interest income | C6: 23432092 | D6: 18474443 | E6: 18975227 | F6: 21851391 | G6: 22101235 | H6: 21889560 | I6: 18823025 | J6: 18883052 | K6: =E6+D6+C6+C6 -> 84313854
B7: Fee and commission income | C7: 7657034 | D7: 7076778 | E7: 7300668 | F7: 7985635 | G7: 6447150 | H7: 6365740 | I7: 5393005 | J7: 4915199 | K7: =E7+D7+C7+C7 -> 29691514
B8: Less: Fee and commission expense | C8: 2038079 | D8: 1887996 | E8: 1898492 | F8: 1729591 | G8: 1411595 | H8: 1575925 | I8: 1305318 | J8: 1269724
B9: Net fee and commission income | C9: 5618955 | D9: 5188782 | E9: 5402176 | F9: 6256044 | G9: 5035555 | H9: 4789815 | I9: 4087687 | J9: 3645475
B10: Net gains/(losses) from trading | C10: 3381671 | D10: -6555889 | E10: -8975464 | F10: 1173354 | G10: 2022197 | H10: 8560357 | I10: 23541542 | J10: -101050
B11: Net gains/(losses) from derecognition of financial assets | C11: 1713760 | D11: 587244 | E11: 337266 | F11: 105790 | G11: 106832 | H11: 49119 | I11: 15143 | J11: 25076
B12: Net other operating income | C12: 1783762 | D12: 7538276 | E12: 9547744 | F12: 3412648 | G12: 5339482 | H12: -300824 | I12: -12223305 | J12: 2194282
B13: Total operating income | C13: 35930240 | D13: 25232856 | E13: 25286949 | F13: 32799227 | G13: 34605301 | H13: 34988027 | I13: 34244092 | J13: 24646835
B14: Less : Impairment charges and other losses | C14: 12571147 | D14: 6413788 | E14: 6797175 | F14: 19652653 | G14: 17052988 | H14: 29258063 | I14: 5960556 | J14: 7142508
B15: Net operating income | C15: 23359093 | D15: 18819068 | E15: 18489774 | F15: 13146574 | G15: 17552313 | H15: 5729964 | I15: 28283536 | J15: 17504327
B16: Less: Expenses | C16: 10691452 | D16: 10607104 | E16: 10677690 | F16: 10265566 | G16: 7985228 | H16: 9310867 | I16: 8720580 | J16: 8378026
B17: Personnel expenses | C17: 5512768 | D17: 5684029 | E17: 5612486 | F17: 5148402 | G17: 5055534 | H17: 4972094 | I17: 4612253 | J17: 4639350
B18: Depreciation and amortisation | C18: 995181 | D18: 1020578 | E18: 1063760 | F18: 968895 | G18: 905454 | H18: 906117 | I18: 817905 | J18: 798333
B19: Other operating expenses | C19: 4183503 | D19: 3902497 | E19: 4001444 | F19: 4148269 | G19: 2024240 | H19: 3432656 | I19: 3290422 | J19: 2940343
... B26: Profit for the period | C26: 6473131 | D26: 3931444 | E26: 4359030 | F26: 8939067 | G26: 6282655 | H26: -2596954 | I26: 11774704 | J26: 5272945
B27: Profit attributable to:
B28: Equity holders of the Bank | C28: 6233402 | D28: 3750123 | E28: 4216403 | F28: 8775188 | G28: 6095730 | H28: -2743585 | I28: 11684581 | J28: 5217687
B29: Non-controlling interest | C29: 239729 | D29: 181321 | E29: 142627 | F29: 163879 | G29: 186925 | H29: 146631 | I29: 90123 | J29: 55258
B30: Profit for the period | C30: 6473131 | D30: 3931444 | E30: 4359030 | F30: 8939067 | G30: 6282655 | H30: -2596954 | I30: 11774704 | J30: 5272945
B32: Earnings per share | C32: 4.75 | D32: 2.86 | E32: 3.21 | F32: 7.08 | G32: 4.92 | H32: -2.21 | I32: 9.42 | J32: 4.37

Sheet Sheet1
B3: For the year ended December 31,
B4: (LKR '000 except per share data) | C4: 2017 | D4: 2018 | E4: 2019
B5: INCOME STATEMENT
B6: Gross income | C6: - | D6: - | E6: 150741129
B7: Interest income | C7: - | D7: - | E7: 129287743
B8: Less: Interest expense | C8: - | D8: - | E8: 80931352
B9: Net interest income | C9: - | D9: - | E9: 48356391
B10: Fee and commission income | C10: - | D10: - | E10: 12874966
B11: Less: Fee and commission expense | C11: - | D11: - | E11: 2123128
B12: Net fee and commission income | C12: - | D12: - | E12: 10751838
B13: Net gains/(losses) from trading | C13: - | D13: - | E13: 1360833
B14: Net gains/(losses) from derecognition of financial assets | C14: - | D14: - | E14: 1135711
B15: Net other operating income | C15: - | D15: - | E15: 6081876
B16: Total operating income | C16: - | D16: - | E16: 67686649
B17: Less: Impairment charges and other losses | C17: - | D17: - | E17: 11331525
B18: Net operating income | C18: - | D18: - | E18: 56355126
B19: Less: Expenses
B20: Personnel expenses | C20: - | D20: - | E20: 14408914
B21: Depreciation and amortisation | C21: - | D21: - | E21: 2841264
B22: Other operating expenses | C22: - | D22: - | E22: 8875316
B23: Total operating expenses | C23: - | D23: - | E23: 26125494
B24: Operating profit before taxes on financial services | C24: - | D24: - | E24: 30229632
B25: Less: Taxes on financial services | C25: - | D25: - | E25: 7255728
B26: Operating profit after taxes on financial services | C26: - | D26: - | E26: 22973904
B27: Share of profit/(loss) of associate, net of tax | C27: - | D27: - | E27: 9992
B28: Profit before tax | C28: - | D28: - | E28: 22983896
B29: Less: Income tax expense/(reversal) | C29: - | D29: - | E29: 5563500
B30: Profit for the year | C30: - | D30: - | E30: 17420396
B31: Profit attributable to: Equity holders of the Bank | C31: - | D31: - | E31: 17263259
... B36: Diviend per share | C36: - | D36: - | E36: 5
B38: OCI
B39: Transfer of FV losses reclassification of debt from FVTOCI to AC | C39: - | D39: - | E39: -
B41: IS check | C41: =IF(C18-C23-C25+C27-C29-C30+C31+C32-C33=0,"OK","FLAG") -> #VALUE! | D41: =IF(D18-D23-D25+D27-D29-D30+D31+D32-D33=0,"OK","FLAG") -> #VALUE! | E41: =IF(E18-E23-E25+E27-E29-E30+E31+E32-E33=0,"OK","FLAG") -> FLAG
B43: BALANCE SHEET
B44: Assets
B45: Cash and cash equivalents | C45: - | D45: - | E45: 53681118
B46: Balances with Central Banks | C46: - | D46: - | E46: 46101232
B47: Placements with banks | C47: - | D47: - | E47: 24903809
B48: Securities purchased under resale agreements | C48: - | D48: - | E48: 13147534
B49: Derivative financial assets | C49: - | D49: - | E49: 1830927
...
