Workbook

Sheet FS (2)
B3: For the year ended December 31,
B4: (LKR '000 except per share data) | C4: 2017 | D4: 2018 | E4: 2019 | F4: 2020 | G4: 2021 | H4: 2022 | I4: 2023F | J4: 2024F | K4: 2025F | L4: 2026F
B5: INCOME STATEMENT
B6: Gross income | C6: 115605156 | D6: 139657195 | E6: 150741129 | F6: 151966413 | G6: 163675312 | H6: 280386944 | I6: =I7+I10+I13+I14+I15 -> 0 | J6: =J7+J10+J13+J14+J15 -> 0 | K6: =K7+K10+K13+K14+K15 -> 0 | L6: =L7+L10+L13+L14+L15 -> 0
B7: Interest income | C7: 104049102 | D7: 118551239 | E7: 129287743 | F7: 124087713 | G7: 132818178 | H7: 222393079
B8: Less: Interest expense | C8: 64481804 | D8: 72933030 | E8: 80931352 | F8: 73218911 | G8: 66401846 | H8: 137727868
B9: Net interest income | C9: 39567298 | D9: 45618209 | E9: 48356391 | F9: 50868802 | G9: 66416332 | H9: 84665211 | I9: =I7-I8 -> 0 | J9: =J7-J8 -> 0 | K9: =K7-K8 -> 0 | L9: =L7-L8 -> 0
B10: Fee and commission income | C10: 10510800 | D10: 12494090 | E10: 12874966 | F10: 11839689 | G10: 15917337 | H10: 26191530
B11: Less: Fee and commission expense | C11: 1586334 | D11: 1859698 | E11: 2123128 | F11: 2018014 | G11: 3675143 | H11: 6022429
B12: Net fee and commission income | C12: 8924466 | D12: 10634392 | E12: 10751838 | F12: 9821675 | G12: 12242194 | H12: 20169101 | I12: =I10-I11 -> 0 | J12: =J10-J11 -> 0 | K12: =K10-K11 -> 0 | L12: =L10-L11 -> 0
B13: Net gains/(losses) from trading | C13: 233956 | D13: -3033236 | E13: 1360833 | F13: 1878060 | G13: 1936007 | H13: 35297450
B14: Net gains/(losses) from derecognition of financial assets | C14: 91272 | D14: 272004 | E14: 1135711 | F14: 6390197 | G14: 3001574 | H14: 276884
B15: Net other operating income | C15: 720026 | D15: 11373098 | E15: 6081876 | F15: 7770754 | G15: 10002216 | H15: -3771999
B16: Total operating income | C16: 49537018 | D16: 64864467 | E16: 67686649 | F16: 76729488 | G16: 93598323 | H16: 136636647 | I16: =I9+I12+I13+I14+I15 -> 0 | J16: =J9+J12+J13+J14+J15 -> 0 | K16: =K9+K12+K13+K14+K15 -> 0 | L16: =L9+L12+L13+L14+L15 -> 0
B17: Less: Impairment charges and other losses | C17: 989315 | D17: 8833362 | E17: 11331523 | F17: 21419532 | G17: 25139926 | H17: 71924260
B18: Net operating income | C18: 48547703 | D18: 56031105 | E18: 56355126 | F18: 55309956 | G18: 68458397 | H18: 64712387 | I18: =I16-I17 -> 0 | J18: =J16-J17 -> 0 | K18: =K16-K17 -> 0 | L18: =L16-L17 -> 0
B19: Less: Expenses
B20: Personnel expenses | C20: 11338517 | D20: 13289668 | E20: 14408914 | F20: 14992748 | G20: 16799212 | H20: 19788283
B21: Depreciation and amortisation | C21: 1416927 | D21: 1603118 | E21: 2841264 | F21: 3102695 | G21: 3220066 | H21: 3598371
B22: Other operating expenses | C22: 7618993 | D22: 8993958 | E22: 8875316 | F22: 8167170 | G22: 9638461 | H22: 12895587
B23: Total operating expenses | C23: 20374437 | D23: 23886744 | E23: 26125494 | F23: 26262613 | G23: 29657739 | H23: 36282241 | I23: =I20+I21+I22 -> 0 | J23: =J20+J21+J22 -> 0 | K23: =K20+K21+K22 -> 0 | L23: =L20+L21+L22 -> 0
B24: Operating profit before taxes on financial services | C24: 28173266 | D24: 32144361 | E24: 30229632 | F24: 29047343 | G24: 38800658 | H24: 28430146 | I24: =I18-I23 -> 0
B25: Less: Taxes on financial services | C25: 4896620 | D25: 6051861 | E25: 7255728 | F25: 4531381 | G25: 5845230 | H25: 3921381
B26: Operating profit after taxes on financial services | C26: 23276646 | D26: 26092500 | E26: 22973904 | F26: 24515962 | G26: 32955428 | H26: 24508765 | I26: =I24-I25 -> 0 | J26: =J24-J25 -> 0 | K26: =K24-K25 -> 0 | L26: =L24-L25 -> 0
B27: Share of profit/(loss) of associate, net of tax | C27: 3678 | D27: 6048 | E27: 9992 | F27: 3898 | G27: 1896 | H27: -3727
B28: Profit before tax | C28: 23280324 | D28: 26098548 | E28: 22983896 | F28: 24519860 | G28: 32957324 | H28: 24505038 | I28: =I26+I27 -> 0 | J28: =J26+J27 -> 0 | K28: =K26+K27 -> 0 | L28: =L26+L27 -> 0
B29: Less: Income tax expense/(reversal) | C29: 6653817 | D29: 8235717 | E29: 5563500 | F29: 7433063 | G29: 8667036 | H29: 105566
B30: Profit for the year | C30: 16626507 | D30: 17862831 | E30: 17420396 | F30: 17086797 | G30: 24290288 | H30: 24399472 | I30: =I28-I29 -> 0 | J30: =J28-J29 -> 0 | K30: =K28-K29 -> 0 | L30: =L28-L29 -> 0
B31: Profit attributable to: Equity holders of the Bank | C31: 16605963 | D31: 17734706 | E31: 17263259 | F31: 16939950 | G31: 24062469 | H31: 23811914
B32: Non-controlling interest | C32: 20544 | D32: 128125 | E32: 157137 | F32: 146847 | G32: 227819 | H32: 587558
B33: Profit for the year | C33: 16626507 | D33: 17862831 | E33: 17420396 | F33: 17086797 | G33: 24290288 | H33: 24399472 | I33: =I30 -> 0 | J33: =J30 -> 0 | K33: =K30 -> 0 | L33: =L30 -> 0
B34: Earnings per share Basic earnings per ordinary share (Rs.) | C34: 17.05 | D34: 17.55 | E34: 16.41 | F34: 15.7 | G34: 19.41 | H34: 19.21
B35: Diluted earnings per ordinary share (Rs.) | C35: 17.03 | D35: 17.55 | E35: 16.41 | F35: 15.7 | G35: 19.41 | H35: 19.21
B37: OCI
B38: Transfer of FV losses reclassification of debt from FVTOCI to AC | G38: 0 | H38: 26481256
B40: IS check | C40: =IF(C18-C23-C25+C27-C29-C30=0,"OK","FLAG") -> OK | D40: =IF(D18-D23-D25+D27-D29-D30=0,"OK","FLAG") -> OK | E40: =IF(E18-E23-E25+E27-E29-E30=0,"OK","FLAG") -> OK | F40: =IF(F18-F23-F25+F27-F29-F30=0,"OK","FLAG") -> OK | G40: =IF(G18-G23-G25+G27-G29-G30=0,"OK","FLAG") -> OK | H40: =IF(H18-H23-H25+H27-H29-H30=0,"OK","FLAG") -> OK
B42: BALANCE SHEET
B43: Assets
B44: Cash and cash equivalents | C44: 34673424 | D44: 44355962 | E44: 53681118 | F44: 51255030 | G44: 69335379 | H44: 151109490
B45: Balances with Central Banks | C45: 45546349 | D45: 55406535 | E45: 46101232 | F45: 115358732 | G45: 56777465 | H45: 78597120
...

Sheet Cover
B3: COMMERCIAL BANK OF CEYLON PLC
B4: COMB N
B5: COMB X

Sheet FS
V1: correct
V2: wrong
B3: For the year ended December 31, | V3: not in report
B4: (LKR '000 except per share data) | C4: 2017 | D4: 2018 | E4: 2019 | F4: 2020 | G4: 2021 | I4: 2022 | J4: 2023F | K4: 2024F | L4: 2025F | M4: 2026F | O4: Annualised | P4: 9M Sep23 | Q4: 1H2023 | R4: 1H2022
B5: INCOME STATEMENT
B6: Gross income | C6: 115605156 | D6: 139657195 | E6: 150741129 | F6: 151966413 | G6: 163675312 | I6: 280386944 | J6: =J7+J10+J13+J14+J15 -> 3.4870888e+08 | K6: =K7+K10+K13+K14+K15 -> 3.6286483e+08 | L6: =L7+L10+L13+L14+L15 -> 4.1272143e+08 | M6: =M7+M10+M13+M14+M15 -> 4.6464828e+08 | O6: =P6/9*12 -> 3.4128382e+08 | P6: 255962864 | Q6: 167668267 | R6: 119517450 | S6: =Q6*2 -> 335336534
B7: Interest income | C7: 104049102 | D7: 118551239 | E7: 129287743 | F7: 124087713 | G7: 132818178 | I7: 222393079 | J7: =Drivers!I7 -> 3.0585734e+08 | K7: =Drivers!J7 -> 2.9513936e+08 | L7: =Drivers!K7 -> 3.3784948e+08 | M7: =Drivers!L7 -> 3.8175485e+08 | O7: =P7/9*12 -> 2.9942669e+08 | P7: 224570014 | Q7: 150811644 | R7: 88116673 | S7: =Q7*2 -> 301623288
B8: Less: Interest expense | C8: 64481804 | D8: 72933030 | E8: 80931352 | F8: 73218911 | G8: 66401846 | I8: 137727868 | J8: =Drivers!I58 -> 2.2269493e+08 | K8: =Drivers!J58 -> 2.3202049e+08 | L8: =Drivers!K58 -> 2.6615841e+08 | M8: =Drivers!L58 -> 3.0080788e+08 | O8: =P8/9*12 -> 2.18251e+08 | P8: 163688252 | Q8: 113361974 | R8: 47404088 | S8: =Q8*2 -> 226723948
B9: Net interest income | C9: 39567298 | D9: 45618209 | E9: 48356391 | F9: 50868802 | G9: 66416332 | I9: 84665211 | J9: =J7-J8 -> 83162406 | K9: =K7-K8 -> 63118873 | L9: =L7-L8 -> 71691068 | M9: =M7-M8 -> 80946963 | O9: =P9/9*12 -> 81175683 | P9: 60881762 | Q9: 37449670 | R9: 40712585 | S9: =Q9*2 -> 74899340
B10: Fee and commission income | C10: 10510800 | D10: 12494090 | E10: 12874966 | F10: 11839689 | G10: 15917337 | I10: 26191530 | J10: =Drivers!I78 -> 30373717 | K10: =Drivers!J78 -> 35658826 | L10: =Drivers!K78 -> 41280198 | M10: =Drivers!L78 -> 47701081 | O10: =P10/9*12 -> 29379307 | P10: 22034480 | Q10: 14377446 | R10: 11758745 | S10: =Q10*2 -> 28754892
B11: Less: Fee and commission expense | C11: 1586334 | D11: 1859698 | E11: 2123128 | F11: 2018014 | G11: 3675143 | I11: 6022429 | J11: =Drivers!I93 -> 7593429.2 | K11: =Drivers!J93 -> 8201529.9 | L11: =Drivers!K93 -> 9494445.4 | M11: =Drivers!L93 -> 10971249 | O11: =P11/9*12 -> 7766089.3 | P11: 5824567 | Q11: 3786488 | R11: 2881243 | S11: =Q11*2 -> 7572976
B12: Net fee and commission income | C12: 8924466 | D12: 10634392 | E12: 10751838 | F12: 9821675 | G12: 12242194 | I12: 20169101 | J12: =J10-J11 -> 22780287 | K12: =K10-K11 -> 27457296 | L12: =L10-L11 -> 31785752 | M12: =M10-M11 -> 36729832 | O12: =P12/9*12 -> 21613217 | P12: 16209913 | Q12: 10590958 | R12: 8877502 | S12: =Q12*2 -> 21181916
B13: Net gains/(losses) from trading | C13: 233956 | D13: -3033236 | E13: 1360833 | F13: 1878060 | G13: 1936007 | I13: 35297450 | J13: =Drivers!I106 -> -16199576 | K13: =Drivers!J106 -> 1955367.1 | L13: =Drivers!K106 -> 1974920.7 | M13: =Drivers!L106 -> 1994669.9 | O13: =P13/9*12 -> -16199576 | P13: -12149682 | Q13: -15531353 | R13: 32101899 | S13: =Q13*2 -> -31062706
B14: Net gains/(losses) from derecognition of financial assets | C14: 91272 | D14: 272004 | E14: 1135711 | F14: 6390197 | G14: 3001574 | I14: 276884 | J14: =P14/9*12 -> 3517693.3 | K14: =J14*1.05 -> 3693578 | L14: =K14*1.05 -> 3878256.9 | M14: =L14*1.05 -> 4072169.7 | O14: =P14/9*12 -> 3517693.3 | P14: 2638270 | Q14: 924510 | R14: 64262 | S14: =Q14*2 -> 1849020
B15: Net other operating income | C15: 720026 | D15: 11373098 | E15: 6081876 | F15: 7770754 | G15: 10002216 | I15: -3771999 | J15: =Drivers!I123 -> 25159709 | K15: =Drivers!J123 -> 26417695 | L15: =Drivers!K123 -> 27738580 | M15: =Drivers!L123 -> 29125509 | O15: =P15/9*12 -> 25159709 | P15: 18869782 | Q15: 17086020 | R15: -12524129 | S15: =Q15*2 -> 34172040
B16: Total operating income | C16: 49537018 | D16: 64864467 | E16: 67686649 | F16: 76729488 | G16: 93598323 | I16: 136636647 | J16: =J9+J12+J13+J14+J15 -> 1.1842052e+08 | K16: =K9+K12+K13+K14+K15 -> 1.2264281e+08 | L16: =L9+L12+L13+L14+L15 -> 1.3706858e+08 | M16: =M9+M12+M13+M14+M15 -> 1.5286914e+08 | O16: =P16/9*12 -> 1.1526673e+08 | P16: 86450045 | Q16: 50519805 | R16: 69232119 | S16: =Q16*2 -> 101039610
B17: Less: Impairment charges and other losses | C17: 989315 | D17: 8833362 | E17: 11331523 | F17: 21419532 | G17: 25139926 | I17: 71924260 | J17: =Drivers!I138 -> 35328926 | K17: =Drivers!J138 -> 30095011 | L17: =Drivers!K138 -> 34609262 | M17: =Drivers!L138 -> 39800652 | O17: =P17/9*12 -> 34376147 | P17: 25782110 | Q17: 13210963 | R17: 35218619 | S17: =Q17*2 -> 26421926
B18: Net operating income | C18: 48547703 | D18: 56031105 | E18: 56355126 | F18: 55309956 | G18: 68458397 | I18: 64712387 | J18: =J16-J17 -> 83091594 | K18: =K16-K17 -> 92547798 | L18: =L16-L17 -> 1.0245931e+08 | M18: =M16-M17 -> 1.1306849e+08 | O18: =P18/9*12 -> 80890580 | P18: 60667935 | Q18: 37308842 | R18: 34013500 | S18: =Q18*2 -> 74617684
B19: Less: Expenses | O19: =P19/9*12 -> 0 | S19: =Q19*2 -> 0
B20: Personnel expenses | C20: 11338517 | D20: 13289668 | E20: 14408914 | F20: 14992748 | G20: 16799212 | I20: 19788283 | J20: =Drivers!I155 -> 21767111 | K20: =Drivers!J155 -> 23943822 | L20: =Drivers!K155 -> 26338205 | M20: =Drivers!L155 -> 28972025 | O20: =P20/9*12 -> 22412377 | P20: 16809283 | Q20: 11296515 | R20: 9584347 | S20: =Q20*2 -> 22593030
B21: Depreciation and amortisation | C21: 1416927 | D21: 1603118 | E21: 2841264 | F21: 3102695 | G21: 3220066 | I21: 3598371 | J21: =Drivers!I172 -> 4116991 | K21: =Drivers!J172 -> 4240227.2 | L21: =Drivers!K172 -> 4381833.5 | M21: =Drivers!L172 -> 4529601.5 | O21: =P21/9*12 -> 4106025.3 | P21: 3079519 | Q21: 2084338 | R21: 1724022 | S21: =Q21*2 -> 4168676
B22: Other operating expenses | C22: 7618993 | D22: 8993958 | E22: 8875316 | F22: 8167170 | G22: 9638461 | I22: 12895587 | J22: =Drivers!I184 -> 16764263 | K22: =Drivers!J184 -> 20117116 | L22: =Drivers!K184 -> 24140539 | M22: =Drivers!L184 -> 28968647 | O22: =P22/9*12 -> 16116592 | P22: 12087444 | Q22: 7903941 | R22: 6723078 | S22: =Q22*2 -> 15807882
B23: Total operating expenses | C23: 20374437 | D23: 23886744 | E23: 26125494 | F23: 26262613 | G23: 29657739 | I23: 36282241 | J23: =J20+J21+J22 -> 42648365 | K23: =K20+K21+K22 -> 48301165 | L23: =L20+L21+L22 -> 54860577 | M23: =M20+M21+M22 -> 62470273 | O23: =P23/9*12 -> 42634995 | P23: 31976246 | Q23: 21284794 | R23: 18031447 | S23: =Q23*2 -> 42569588
B24: Operating profit before taxes on financial services | C24: 28173266 | D24: 32144361 | E24: 30229632 | F24: 29047343 | G24: 38800658 | I24: 28430146 | J24: =J18-J23 -> 40443229 | K24: =K18-K23 -> 44246633 | L24: =L18-L23 -> 47598738 | M24: =M18-M23 -> 50598219 | O24: =P24/9*12 -> 38255585 | P24: 28691689 | Q24: 16024048 | R24: 15982053 | S24: =Q24*2 -> 32048096
B25: Less: Taxes on financial services | C25: 4896620 | D25: 6051861 | E25: 7255728 | F25: 4531381 | G25: 5845230 | I25: 3921381 | J25: =Drivers!I196 -> 4893717.4 | K25: =Drivers!J196 -> 5902787.2 | L25: =Drivers!K196 -> 6756989.5 | M25: =Drivers!L196 -> 7635097 | O25: =P25/9*12 -> 4886169.3 | P25: 3664627 | Q25: 1933968 | R25: 2602781 | S25: =Q25*2 -> 3867936
B26: Operating profit after taxes on financial services | C26: 23276646 | D26: 26092500 | E26: 22973904 | F26: 24515962 | G26: 32955428 | I26: 24508765 | J26: =J24-J25 -> 35549511 | K26: =K24-K25 -> 38343846 | L26: =L24-L25 -> 40841748 | M26: =M24-M25 -> 42963122 | O26: =P26/9*12 -> 33369416 | P26: 25027062 | Q26: 14090080 | R26: 13379272 | S26: =Q26*2 -> 28180160
B27: Share of profit/(loss) of associate, net of tax | C27: 3678 | D27: 6048 | E27: 9992 | F27: 3898 | G27: 1896 | I27: -3727 | J27: =P27/9*12 -> 5197.3333 | K27: =J27*1.01 -> 5249.3067 | L27: =K27*1.01 -> 5301.7997 | M27: =L27*1.01 -> 5354.8177 | O27: =P27/9*12 -> 5197.3333 | P27: 3898 | Q27: 2352 | R27: -3476 | S27: =Q27*2 -> 4704
B28: Profit before tax | C28: 23280324 | D28: 26098548 | E28: 22983896 | F28: 24519860 | G28: 32957324 | I28: 24505038 | J28: =J26+J27 -> 35554709 | K28: =K26+K27 -> 38349095 | L28: =L26+L27 -> 40847050 | M28: =M26+M27 -> 42968476 | O28: =P28/9*12 -> 33374613 | P28: 25030960 | Q28: 14092432 | R28: 13375796 | S28: =Q28*2 -> 28184864
B29: Less: Income tax expense/(reversal) | C29: 6653817 | D29: 8235717 | E29: 5563500 | F29: 7433063 | G29: 8667036 | I29: 105566 | J29: =Drivers!I206 -> 14932978 | K29: =Drivers!J206 -> 11504728 | L29: =Drivers!K206 -> 12254115 | M29: =Drivers!L206 -> 12890543 | O29: =P29/9*12 -> 13689807 | P29: 10267355 | Q29: 5801958 | R29: 4198046 | S29: =Q29*2 -> 11603916
B30: Profit for the year | C30: 16626507 | D30: 17862831 | E30: 17420396 | F30: 17086797 | G30: 24290288 | I30: 24399472 | J30: =J28-J29 -> 20621731 | K30: =K28-K29 -> 26844366 | L30: =L28-L29 -> 28592935 | M30: =M28-M29 -> 30077933 | O30: =P30/9*12 -> 19684807 | P30: 14763605 | Q30: 8290474 | R30: 9177750 | S30: =Q30*2 -> 16580948
B31: Profit attributable to: Equity holders of the Bank | C31: 16605963 | D31: 17734706 | E31: 17263259 | F31: 16939950 | G31: 24062469 | I31: 23811914 | J31: =J30*0.96 -> 19796862 | K31: =K30*0.96 -> 25770592 | L31: =L30*0.96 -> 27449218 | M31: =M30*0.96 -> 28874816 | O31: =P31/9*12 -> 18933237 | P31: 14199928 | Q31: 7966526 | R31: 8940996
B32: Non-controlling interest | C32: 20544 | D32: 128125 | E32: 157137 | F32: 146847 | G32: 227819 | I32: 587558 | J32: =J30*0.04 -> 824869.24 | K32: =K30*0.04 -> 1073774.7 | L32: =L30*0.04 -> 1143717.4 | M32: =M30*0.04 -> 1203117.3 | O32: =P32/9*12 -> 751569.33 | P32: 563677 | Q32: 323948 | R32: 236754
B33: Profit for the year | C33: 16626507 | D33: 17862831 | E33: 17420396 | F33: 17086797 | G33: 24290288 | I33: 24399472 | J33: =J30 -> 20621731 | K33: =K30 -> 26844366 | L33: =L30 -> 28592935 | M33: =M30 -> 30077933 | O33: =P33/9*12 -> 19684807 | P33: =P30 -> 14763605 | Q33: =Q30 -> 8290474 | R33: =R30 -> 9177750
B34: Earnings per share Basic earnings per ordinary share (Rs.) | C34: 17.05 | D34: 17.55 | E34: 16.41 | F34: 15.7 | G34: 19.41 | I34: 19.21 | J34: =J31*1000/Drivers!I586 -> 15.064716 | K34: =K31*1000/Drivers!J586 -> 19.610515 | L34: =L31*1000/Drivers!K586 -> 20.88789 | M34: =M31*1000/Drivers!L586 -> 21.97272 | P34: 10.81 | Q34: 6.07 | R34: 7.21
B35: Diluted earnings per ordinary share (Rs.) | C35: 17.03 | D35: 17.55 | E35: 16.41 | F35: 15.7 | G35: 19.41 | I35: 19.21 | P35: 10.81 | Q35: 6.07 | R35: 7.21
B36: Diviend per share | D36: 6.5 | E36: 6.5 | F36: 6.5 | G36: 7.5 | I36: 4.5 | J36: ='charts 1'!N23 -> 4.5 | K36: =-Drivers!J619*1000/Drivers!J586 -> 6.8636802 | L36: =-Drivers!K619*1000/Drivers!K586 -> 7.3107615 | M36: =-Drivers!L619*1000/Drivers!L586 -> 7.6904522
B38: OCI
B39: Transfer of FV losses reclassification of debt from FVTOCI to AC | G39: 0 | I39: 26481256
B41: IS check | C41: =IF(C18-C23-C25+C27-C29-C30+C31+C32-C33=0,"OK","FLAG") -> OK | D41: =IF(D18-D23-D25+D27-D29-D30+D31+D32-D33=0,"OK","FLAG") -> OK | E41: =IF(E18-E23-E25+E27-E29-E30+E31+E32-E33=0,"OK","FLAG") -> OK | F41: =IF(F18-F23-F25+F27-F29-F30+F31+F32-F33=0,"OK","FLAG") -> OK | G41: =IF(G18-G23-G25+G27-G29-G30+G31+G32-G33=0,"OK","FLAG") -> OK | I41: =IF(I18-I23-I25+I27-I29-I30+I31+I32-I33=0,"OK","FLAG") -> OK | J41: =J18-J23-J25+J27-J29-J30+J31+J32-J33 -> 0 | K41: =K18-K23-K25+K27-K29-K30+K31+K32-K33 -> 0 | L41: =L18-L23-L25+L27-L29-L30+L31+L32-L33 -> 0 | M41: =M18-M23-M25+M27-M29-M30+M31+M32-M33 -> 0 | Q41: =IF(Q18-Q23-Q25+Q27-Q29-Q30=0,"OK","FLAG") -> OK | R41: =IF(R18-R23-R25+R27-R29-R30=0,"OK","FLAG") -> OK
B43: BALANCE SHEET
...

Sheet Valuation
A1: All figures in LKR 000 | D1: 0 | E1: 1 | F1: 2
A2: Residual income | C2: =FS!J4 -> 2023F | D2: =FS!K4 -> 2024F | E2: =FS!L4 -> 2025F | F2: =FS!M4 -> 2026F
A3: Equity | C3: =FS!J80 -> 2.2956477e+08 | D3: =FS!K80 -> 2.5403473e+08 | E3: =FS!L80 -> 2.7757718e+08 | F3: =FS!M80 -> 3.0210087e+08
A4: ROE | C4: =FS!J30/FS!J82 -> 0.087940259 | D4: =FS!K30/FS!K82 -> 0.10323137 | E4: =FS!L30/FS!L82 -> 0.1004223 | F4: =FS!M30/FS!M82 -> 0.096883779
A5: Net income | C5: =FS!J31 -> 19796862 | D5: =FS!K31 -> 25770592 | E5: =FS!L31 -> 27449218 | F5: =FS!M31 -> 28874816
A6: Equity charge | C6: =C3*C4 -> 20187985 | D6: =D3*D4 -> 26224354 | E6: =E3*E4 -> 27874939 | F6: =F3*F4 -> 29268674
A7: Residual income | C7: =C5-C6 -> -391123.5 | D7: =D5-D6 -> -453761.69 | E7: =E5-E6 -> -425721.12 | F7: =F5-F6 -> -393858.12
A8: Terminal value | F8: =(F7*(1+B32))/(B26-B32) -> -1505842.1
A9: Discount factor | D9: =1/((1+$B$26)^D1) -> 1 | E9: =1/((1+$B$26)^E1) -> 0.76958596 | F9: =1/((1+$B$26)^F1) -> 0.59226255
A10: PV of RI + terminal value | D10: =D7*D9 -> -453761.69 | E10: =E7*E9 -> -327629 | F10: =(F7*F9)+(F8*F9) -> -1125121.3
A12: Residual Income (RI) Valuation | B12: (LKR '000)
A13: Present Value of Residual Income | B13: =SUM(E10:F10) -> -1452750.3
A14: No of shares ('000) | B14: =Drivers!I586/1000 -> 1314121.1
A15: Residual Income per share | B15: =(B13)/B14 -> -1.1054919
A16: Net Asset Value Per Share | B16: =FS!P85 -> 162.7
A17: Value per share | B17: =B15+B16 -> 161.59451
A22: Cost of equity
A23: Risk Free rate | B23: 0.12
A24: Equity Risk Premium | B24: 0.23
A25: Beta | B25: 0.78
A26: Cost of Equity | B26: =B23+(B24*B25) -> 0.2994
A28: g = b x ROE
A29: 1-payout
A30: ROE (2023E) | B30: =FS!J30/FS!J82 -> 0.087940259
A32: Estiamted g | B32: 0.03
A37: PBV based valuation
A45: Justified Price to Book Valuation
A46: ROE (2024 expected) | B46: =D4 -> 0.10323137
A47: Growth rate (g) | B47: =B32 -> 0.03
A48: Cost of equity (r) | B48: =B26 -> 0.2994
A49: Justified PBV = (ROE - g)/ (r - g) | B49: =(B46-B47)/(B48-B47) -> 0.27183137
A50: Net Asset Value Per Share (2024E) | B50: =Drivers!J591 -> 193.3115
A51: Value per share | B51: =B49*B50 -> 52.548131
A52: Peer PBV | B52: =AVERAGE(C71:C77) -> 0.44728571
A53: Curent NAVPS | B53: =FS!P85 -> 162.7
A57: Forward PE Valuation
A58: Peer average PE | B58: =AVERAGE(B71:B77) -> 3.6592857
A59: Expected forward PE | B59: 5
A60: EPS (2024E) | B60: =FS!K34 -> 19.610515
A61: Value per share | B61: =B59*B60 -> 98.052574
...

Sheet Drivers
B3: For the year ended December 31, | N3: Annualised | P3: Period | Q3: Quarter
B4: (LKR '000 except per share data) | C4: 2017 | D4: 2018 | E4: 2019 | F4: 2020 | G4: 2021 | H4: 2022 | I4: 2023F | J4: 2024F | K4: 2025F | L4: 2026F | N4: 45192 | O4: 45100 | P4: 45078
B5: INCOME STATEMENT
B7: Interest income | C7: 104049102 | D7: 118551239 | E7: 129287743 | F7: 124087713 | G7: 132818178 | H7: 222393079 | I7: =I13+SUM(I14:I19) -> 3.0585734e+08 | J7: =J13+SUM(J14:J19) -> 2.9513936e+08 | K7: =K13+SUM(K14:K19) -> 3.3784948e+08 | L7: =L13+SUM(L14:L19) -> 3.8175485e+08 | N7: =FS!P7/9*12 -> 2.9942669e+08 | P7: 150811644 | Q7: 88116673 | R7: =P7*2 -> 301623288
B9: Cash and cash equivalents | C9: 362695 | D9: 411412 | E9: 1290697 | F9: 1053757 | G9: 447742 | H9: 945450 | I9: =FS!I45*Drivers!I55 -> 2055089.1 | J9: =FS!J45*Drivers!J55 -> 1440462 | K9: =FS!K45*Drivers!K55 -> 1491785.1 | L9: =FS!L45*Drivers!L55 -> 2163539.6
B10: Balances with Central Banks | C10: 4400 | D10: 26734 | E10: 62572 | F10: 1175509 | G10: 1299948 | H10: 815979
B11: Placements with Banks | C11: 215909 | D11: 529738 | E11: 931571 | F11: 777425 | G11: 778021 | H11: 1685996 | I11: =I252*I28 -> 1348796.8 | J11: =J252*J28 -> 1416236.6 | K11: =K252*K28 -> 1487048.5 | L11: =L252*L28 -> 1561400.9
B12: Securities purchased under resale agreements | C12: 139153 | D12: 508616 | E12: 1906902 | F12: 836773 | G12: 375398 | H12: 1133583 | I12: =I264*I29 -> 453433.2 | J12: =J264*J29 -> 476104.86 | K12: =K264*K29 -> 499910.1 | L12: =L264*L29 -> 524905.61
B13: Financial assets recognized through profit or loss | C13: 469012 | D13: 323335 | E13: 474478 | F13: 1831327 | G13: 1101385 | H13: 1516691 | I13: =SUM(I9:I12) -> 3857319.1 | J13: =SUM(J9:J12) -> 3332803.5 | K13: =SUM(K9:K12) -> 3478743.7 | L13: =SUM(L9:L12) -> 4249846.1
B14: Derivatives | C14: 24111 | D14: 56173 | E14: 67453 | F14: 34902 | G14: 167377 | H14: 237438 | I14: =I266*I31 -> 166206.6 | J14: =J266*J31 -> 174516.93 | K14: =K266*K31 -> 183242.78 | L14: =L266*L31 -> 192404.92
B15: Other financial instruments | C15: 444901 | D15: 267162 | E15: 407025 | F15: 1796425 | G15: 934008 | H15: 1279253 | I15: =I271*I32 -> 4946643.7 | J15: =J271*J32 -> 7798003.1 | K15: =K271*K32 -> 8577803.4 | L15: =L271*L32 -> 9435583.8
B16: Financial assets at amortized cost - loans and advances to other customers | C16: 78132371 | D16: 95081154 | E16: 100444369 | F16: 84257196 | G16: 79654575 | H16: 144253496 | I16: =I33*I305 -> 2.028142e+08 | J16: =J33*J305 -> 1.8785541e+08 | K16: =K33*K305 -> 2.1976882e+08 | L16: =L33*L305 -> 2.5273414e+08
B17: Financial assets at amortized cost - debt and other financial instruments | C17: 8512118 | D17: 6828671 | E17: 7819563 | F17: 13194851 | G17: 25951467 | H17: 51750895 | I17: =I50*I341 -> 48193316 | J17: =J50*J341 -> 45412106 | K17: =K50*K341 -> 50127260 | L17: =L50*L341 -> 53757016
B18: Financial assets measured at fair value through other comprehensive income | C18: 15349974 | D18: 14478042 | E18: 15091368 | F18: 18053545 | G18: 22034788 | H18: 18995711 | I18: =I52*I384 -> 44543209 | J18: =J52*J384 -> 48997530 | K18: =K52*K384 -> 53897283 | L18: =L52*L384 -> 59287011
B19: Interest accrued on impaired loans and advances to other customers | C19: 861057 | D19: 360876 | E19: 1258339 | F19: 2895955 | G19: 1174854 | H19: 1295278 | I19: =I53*I289 -> 1336443.5 | J19: =J53*J289 -> 1568988.3 | K19: =K53*K289 -> 1816328.7 | L19: =L53*L289 -> 2098847.6
C20: 2413 | D20: 2661 | E20: 7884 | F20: 11375 | G20: 0 | H20: 0
B22: Check | C22: =SUM(C9:C13)+C16+C17+C18+C19+C20-C7 -> 0 | D22: =SUM(D9:D13)+D16+D17+D18+D19+D20-D7 -> 0 | E22: =SUM(E9:E13)+E16+E17+E18+E19+E20-E7 -> 0 | F22: =SUM(F9:F13)+F16+F17+F18+F19+F20-F7 -> 0 | G22: =SUM(G9:G13)+G16+G17+G18+G19+G20-G7 -> 0 | H22: =SUM(H9:H13)+H16+H17+H18+H19+H20-H7 -> 0
B24: Interest rate
B26: Cash and cash equivalents | C26: =C9/FS!C45 -> 0.010460317 | D26: =D9/FS!D45 -> 0.0092752356 | E26: =E9/FS!E45 -> 0.02404378 | F26: =F9/FS!F45 -> 0.020559094 | G26: =G9/FS!G45 -> 0.0064576268 | H26: =H9/FS!I45 -> 0.0062567215 | I26: 0.0062567215 | J26: 0.0062567215 | K26: 0.0062567215 | L26: 0.0062567215
B27: Balances with Central Banks | C27: =C10/FS!C46 -> 9.6604889e-05 | D27: =D10/FS!D46 -> 0.00048250626 | E27: =E10/FS!E46 -> 0.0013572739 | F27: =F10/FS!F46 -> 0.010190031 | G27: =G10/FS!G46 -> 0.022895492 | H27: =H10/FS!I46 -> 0.010381793 | I27: 0.010381793 | J27: 0.010381793 | K27: 0.010381793 | L27: 0.010381793
B28: Placements with Banks | C28: =C11/FS!C47 -> 0.012244411 | D28: =D11/FS!D47 -> 0.026621987 | E28: =E11/FS!E47 -> 0.037406768 | F28: =F11/FS!F47 -> 0.047340841 | G28: =G11/FS!G47 -> 0.062248109 | H28: =H11/FS!I47 -> 0.017547299 | I28: 0.017547299 | J28: 0.017547299 | K28: 0.017547299 | L28: 0.017547299
B29: Securities purchased under resale agreements | C29: =C12/FS!C48 -> #DIV/0! | D29: =D12/FS!D48 -> 0.053462486 | E29: =E12/FS!E48 -> 0.14503876 | F29: =F12/FS!F48 -> #DIV/0! | G29: =G12/FS!G48 -> 0.12511223 | H29: =H12/FS!I48 -> 0.74710145 | I29: 0.74710145 | J29: 0.74710145 | K29: 0.74710145 | L29: 0.74710145
B30: Financial assets recognized through profit or loss
B31: Derivatives | C31: =C14/FS!C49 -> 0.010327962 | D31: =D14/FS!D49 -> 0.0071015512 | E31: =E14/FS!E49 -> 0.036840901 | F31: =F14/FS!F49 -> 0.013236915 | G31: =G14/FS!G49 -> 0.051578062 | H31: =H14/FS!I49 -> 0.028452416 | I31: 0.028452416 | J31: 0.028452416 | K31: 0.028452416 | L31: 0.028452416
B32: Other financial instruments | C32: =C15/C271 -> 0.1008637 | D32: =D15/D271 -> 0.048397449 | E32: =E15/E271 -> 0.018959585 | F32: =F15/F271 -> 0.051050071 | G32: =G15/G271 -> 0.039853349 | H32: =H15/H271 -> 0.051431274 | I32: 0.05 | J32: 0.05 | K32: 0.05 | L32: 0.05
B33: Financial assets at amortized cost - loans and advances to other customers | C33: =C16/FS!C52 -> 0.1052367 | D33: =D16/FS!D52 -> 0.10958949 | E33: =E16/FS!E52 -> 0.11236402 | F33: =F16/FS!F52 -> 0.09260771 | G33: =G16/FS!G52 -> 0.07736578 | H33: =H16/FS!I52 -> 0.12484157 | I33: 0.155 | J33: 0.12484157 | K33: 0.127 | L33: 0.127
B34: Overdrafts | H34: 0.28 | I34: 0.28 | J34: 0.28 | K34: 0.28 | L34: 0.28
B35: Trade finance | H35: 0.155 | I35: 0.155 | J35: 0.155 | K35: 0.155 | L35: 0.155
B36: Lease/hire purchase receivable | H36: 0.16 | I36: 0.16 | J36: 0.16 | K36: 0.16 | L36: 0.16
B37: Credit cards | H37: 0.28 | I37: 0.28 | J37: 0.28 | K37: 0.28 | L37: 0.28
B38: Pawning
B39: Staff loans
B40: Housing loans | H40: 0.15 | I40: 0.15 | J40: 0.15 | K40: 0.15 | L40: 0.15
B41: Personal loans
B42: Term loans
B43: Short term
B44: Long term | H44: =H47+2% -> 0.16 | I44: 0.16 | J44: 0.16 | K44: 0.16 | L44: 0.16
B45: Bills of exchange
B47: Average AWPLR throughout the year | H47: 0.14 | I47: 0.14 | J47: 0.14 | K47: 0.14 | L47: 0.14
B50: Financial assets at amortized cost - debt and other financial instruments | C50: =C17/FS!C53 -> 0.072088775 | D50: =D17/FS!D53 -> 0.076490797 | E50: =E17/FS!E53 -> 0.073039739 | F50: =F17/FS!F53 -> 0.043682949 | G50: =G17/FS!G53 -> 0.067338091 | H50: =H17/FS!I53 -> 0.067945748 | I50: 0.067945748 | J50: 0.067945748 | K50: 0.067945748 | L50: 0.067945748
...

Sheet Ratios
C2: =FS!C4 -> 2017 | D2: =FS!D4 -> 2018 | E2: =FS!E4 -> 2019 | F2: =FS!F4 -> 2020 | G2: =FS!G4 -> 2021 | H2: =FS!I4 -> 2022 | I2: =FS!J4 -> 2023F | J2: =FS!K4 -> 2024F | K2: =FS!L4 -> 2025F | L2: =FS!M4 -> 2026F
B3: Avg. yield on interest earning assets | C3: =FS!C7/(FS!C49+FS!C50+FS!C51+FS!C52+FS!C53+FS!C54) -> 0.10172748 | D3: =FS!D7/(FS!D49+FS!D50+FS!D51+FS!D52+FS!D53+FS!D54) -> 0.10328201 | E3: =FS!E7/(FS!E49+FS!E50+FS!E51+FS!E52+FS!E53+FS!E54) -> 0.1057257 | F3: =FS!F7/(FS!F49+FS!F50+FS!F51+FS!F52+FS!F53+FS!F54) -> 0.081144905 | G3: =FS!G7/(FS!G49+FS!G50+FS!G51+FS!G52+FS!G53+FS!G54) -> 0.074717288 | H3: =FS!I7/(FS!I49+FS!I50+FS!I51+FS!I52+FS!I53+FS!I54) -> 0.10748751 | I3: =FS!J7/(FS!J49+FS!J50+FS!J51+FS!J52+FS!J53+FS!J54) -> 0.13149674 | J3: =FS!K7/(FS!K49+FS!K50+FS!K51+FS!K52+FS!K53+FS!K54) -> 0.1142421 | K3: =FS!L7/(FS!L49+FS!L50+FS!L51+FS!L52+FS!L53+FS!L54) -> 0.11545382 | L3: =FS!M7/(FS!M49+FS!M50+FS!M51+FS!M52+FS!M53+FS!M54) -> 0.11603704
B4: Avg. cost on interest bearing funds | C4: =FS!C8/(FS!C64+FS!C65+FS!C66+FS!C67+FS!C68) -> 0.064837643 | D4: =FS!D8/(FS!D64+FS!D65+FS!D66+FS!D67+FS!D68) -> 0.064595781 | E4: =FS!E8/(FS!E64+FS!E65+FS!E66+FS!E67+FS!E68) -> 0.067518664 | F4: =FS!F8/(FS!F64+FS!F65+FS!F66+FS!F67+FS!F68) -> 0.048096509 | G4: =FS!G8/(FS!G64+FS!G65+FS!G66+FS!G67+FS!G68) -> 0.038326172 | H4: =FS!I8/(FS!I64+FS!I65+FS!I66+FS!I67+FS!I68) -> 0.063778484 | I4: =FS!J8/(FS!J64+FS!J65+FS!J66+FS!J67+FS!J68) -> 0.095531498 | J4: =FS!K8/(FS!K64+FS!K65+FS!K66+FS!K67+FS!K68) -> 0.090014943 | K4: =FS!L8/(FS!L64+FS!L65+FS!L66+FS!L67+FS!L68) -> 0.090526292 | L4: =FS!M8/(FS!M64+FS!M65+FS!M66+FS!M67+FS!M68) -> 0.091290321
B5: Net interest margin | C5: =FS!C9/(FS!C49+FS!C50+FS!C51+FS!C52+FS!C53+FS!C54) -> 0.038684441 | D5: =FS!D9/(FS!D49+FS!D50+FS!D51+FS!D52+FS!D53+FS!D54) -> 0.039742648 | E5: =FS!E9/(FS!E49+FS!E50+FS!E51+FS!E52+FS!E53+FS!E54) -> 0.039543682 | F5: =FS!F9/(FS!F49+FS!F50+FS!F51+FS!F52+FS!F53+FS!F54) -> 0.033264729 | G5: =FS!G9/(FS!G49+FS!G50+FS!G51+FS!G52+FS!G53+FS!G54) -> 0.037362719 | H5: =FS!I9/(FS!I49+FS!I50+FS!I51+FS!I52+FS!I53+FS!I54) -> 0.040920576 | I5: =FS!J9/(FS!J49+FS!J50+FS!J51+FS!J52+FS!J53+FS!J54) -> 0.035753876 | J5: =FS!K9/(FS!K49+FS!K50+FS!K51+FS!K52+FS!K53+FS!K54) -> 0.024431959 | K5: =FS!L9/(FS!L49+FS!L50+FS!L51+FS!L52+FS!L53+FS!L54) -> 0.024499099 | L5: =FS!M9/(FS!M49+FS!M50+FS!M51+FS!M52+FS!M53+FS!M54) -> 0.024604392
B6: Interest rate spread | C6: =C3-C4 -> 0.036889834 | D6: =D3-D4 -> 0.038686225 | E6: =E3-E4 -> 0.038207039 | F6: =F3-F4 -> 0.033048396 | G6: =G3-G4 -> 0.036391117 | H6: =H3-H4 -> 0.043709029 | I6: =I3-I4 -> 0.035965245 | J6: =J3-J4 -> 0.024227159 | ... L6: =L3-L4 -> 0.024746718
B7: Cost to income (operating) | C7: =FS!C23/FS!C16 -> 0.4112972 | D7: =FS!D23/FS!D16 -> 0.36825623 | E7: =FS!E23/FS!E16 -> 0.38597706 | F7: =FS!F23/FS!F16 -> 0.34227536 | G7: =FS!G23/FS!G16 -> 0.31686186 | H7: =FS!I23/FS!I16 -> 0.26553814 | I7: =FS!J23/FS!J16 -> 0.36014337 | J7: =FS!K23/FS!K16 -> 0.3938361 | K7: =FS!L23/FS!L16 -> 0.40024182 | L7: =FS!M23/FS!M16 -> 0.40865195
B8: Cost to income (with impairments) | C8: =(FS!C23+FS!C17)/FS!C6 -> 0.1847993 | D8: =(FS!D23+FS!D17)/FS!D6 -> 0.23428872 | E8: =(FS!E23+FS!E17)/FS!E6 -> 0.24848571 | F8: =(FS!F23+FS!F17)/FS!F6 -> 0.31376765 | G8: =(FS!G23+FS!G17)/FS!G6 -> 0.33479493 | H8: =(FS!I23+FS!I17)/FS!I6 -> 0.38591847 | I8: =(FS!J23/FS!J6) -> 0.12230364 | J8: =(FS!K23/FS!K6) -> 0.13311063 | K8: =(FS!L23/FS!L6) -> 0.13292398 | L8: =(FS!M23/FS!M6) -> 0.13444637
B9: Impairments/ Gross loans | C9: =Drivers!C315/Drivers!C311 -> 0.023682969 | D9: =Drivers!D315/Drivers!D311 -> 0.033792109 | E9: =Drivers!E315/Drivers!E311 -> 0.039557968 | F9: =Drivers!F315/Drivers!F311 -> 0.054093105 | G9: =Drivers!G315/Drivers!G311 -> 0.059681216 | H9: =Drivers!H315/Drivers!H311 -> 0.07276509 | I9: =Drivers!I315/Drivers!I311 -> 0.07148 | J9: =Drivers!J315/Drivers!J311 -> 0.0521 | ... L9: =Drivers!L315/Drivers!L311 -> 0.0412
B10: Net margin | C10: =FS!C30/FS!C6 -> 0.1438215 | D10: =FS!D30/FS!D6 -> 0.12790484 | E10: =FS!E30/FS!E6 -> 0.11556498 | F10: =FS!F30/FS!F6 -> 0.11243798 | G10: =FS!G30/FS!G6 -> 0.14840533 | H10: =FS!I30/FS!I6 -> 0.087020714 | I10: =FS!J30/FS!J6 -> 0.059137383 | J10: =FS!K30/FS!K6 -> 0.073978971 | K10: =FS!L30/FS!L6 -> 0.069279017 | L10: =FS!M30/FS!M6 -> 0.064732691
B11: ROE | C11: =FS!C30/FS!C82 -> 0.15272352 | D11: =FS!D30/FS!D82 -> 0.14812024 | E11: =FS!E30/FS!E82 -> 0.12807845 | F11: =FS!F30/FS!F82 -> 0.106163 | G11: =FS!G30/FS!G82 -> 0.14326114 | H11: =FS!I30/FS!I82 -> 0.11456626 | I11: =FS!J30/FS!J82 -> 0.087940259 | J11: =FS!K30/FS!K82 -> 0.10323137 | K11: =FS!L30/FS!L82 -> 0.1004223 | L11: =FS!M30/FS!M82 -> 0.096883779
B12: ROA | C12: =FS!C30/FS!C62 -> 0.014385023 | D12: =FS!D30/FS!D62 -> 0.013533348 | E12: =FS!E30/FS!E62 -> 0.012364174 | F12: =FS!F30/FS!F62 -> 0.0096946578 | G12: =FS!G30/FS!G62 -> 0.01224623 | H12: =FS!I30/FS!I62 -> 0.0097615306 | I12: =FS!J30/FS!J62 -> 0.0077457677 | J12: =FS!K30/FS!K62 -> 0.009090326 | K12: =FS!L30/FS!L62 -> 0.0084873126 | L12: =FS!M30/FS!M62 -> 0.0079878194
B13: Equity/ total assets | C13: =FS!C82/FS!C62 -> 0.094189964 | D13: =FS!D82/FS!D62 -> 0.09136731 | E13: =FS!E82/FS!E62 -> 0.096535943 | F13: =FS!F82/FS!F62 -> 0.091318616 | G13: =FS!G82/FS!G62 -> 0.085481868 | H13: =FS!I82/FS!I62 -> 0.085204233 | I13: =FS!J82/FS!J62 -> 0.088079883 | J13: =FS!K82/FS!K62 -> 0.088057786 | K13: =FS!L82/FS!L62 -> 0.084516214 | L13: =FS!M82/FS!M62 -> 0.082447439
B14: Deposits / total assets | C14: =FS!C67/FS!C62 -> 0.7416981 | D14: =FS!D67/FS!D62 -> 0.75336136 | E14: =FS!E67/FS!E62 -> 0.75871332 | F14: =FS!F67/FS!F62 -> 0.72999671 | G14: =FS!G67/FS!G62 -> 0.74244872 | H14: =FS!I67/FS!I62 -> 0.79123865 | I14: =FS!J67/FS!J62 -> 0.81094232 | J14: =FS!K67/FS!K62 -> 0.80000087 | K14: =FS!L67/FS!L62 -> 0.79616944 | L14: =FS!M67/FS!M62 -> 0.79274167
B15: Cash / total assets | C15: =FS!C45/FS!C62 -> 0.029998966 | D15: =FS!D45/FS!D62 -> 0.033605236 | E15: =FS!E45/FS!E62 -> 0.038100321 | F15: =FS!F45/FS!F62 -> 0.029080932 | G15: =FS!G45/FS!G62 -> 0.034956233 | H15: =FS!I45/FS!I62 -> 0.060454583 | I15: =FS!J45/FS!J62 -> 0.039783431 | J15: =FS!K45/FS!K62 -> 0.037144427 | K15: =FS!L45/FS!L62 -> 0.047221241 | L15: =FS!M45/FS!M62 -> 0.044651353
B16: Gross income per employee | C16: =FS!C6/FS!C87 -> 23204.568 | D16: =FS!D6/FS!D87 -> 27781.419 | E16: =FS!E6/FS!E87 -> 29778.967 | F16: =FS!F6/FS!F87 -> 30050.705 | G16: =FS!G6/FS!G87 -> 32270.369 | H16: =FS!I6/FS!I87 -> 54752.381 | I16: =FS!J6/FS!J87 -> 67419.707 | J16: =FS!K6/FS!K87 -> 69462.011 | K16: =FS!L6/FS!L87 -> 78223.659 | L16: =FS!M6/FS!M87 -> 87193.49
B17: Dividend payout | F17: =FS!F36/FS!F34 -> 0.41401274 | G17: =FS!G36/FS!G34 -> 0.38639876 | H17: =FS!I36/FS!I34 -> 0.23425299 | I17: =FS!J36/FS!J34 -> 0.29871124 | J17: =FS!K36/FS!K34 -> 0.35 | K17: =FS!L36/FS!L34 -> 0.35 | L17: =FS!M36/FS!M34 -> 0.35
B20: Gross income per service centre | C20: =FS!C6/FS!C88 -> 412875.56 | D20: =FS!D6/FS!D88 -> 490025.25 | E20: =FS!E6/FS!E88 -> 525230.41 | F20: =FS!F6/FS!F88 -> 529499.7 | G20: =FS!G6/FS!G88 -> 570297.25 | H20: =FS!I6/FS!I88 -> 970197.04 | I20: =FS!J6/FS!J88 -> 1200602.1 | J20: =FS!K6/FS!K88 -> 1243125.3 | K20: =FS!L6/FS!L88 -> 1406892.8 | L20: =FS!M6/FS!M88 -> 1576021.9
B22: Net interest spread | F22: =F3-F4 -> 0.033048396 | G22: =G3-G4 -> 0.036391117 | H22: =H3-H4 -> 0.043709029 | I22: =I3-I4 -> 0.035965245 | J22: =J3-J4 -> 0.024227159 | K22: =K3-K4 -> 0.024927528 | L22: =L3-L4 -> 0.024746718

Sheet more Breakups
C1: 2017 | D1: 2018 | E1: 2019 | F1: 2020 | G1: 2021 | H1: 2022
B4: Interest income from government securities
B5: From Sri Lanka | C5: 22331944 | D5: 20458655 | E5: 23158214 | F5: 31523186 | G5: 46873585 | H5: 67938881
B6: Securities purchased under resale agreements | C6: 81635 | D6: 423571 | E6: 1629021 | F6: 618309 | G6: 363247 | H6: 213978
B7: Financial assets recognised through profit or loss | C7: 296520 | D7: 219287 | E7: 277760 | F7: 662961 | G7: 418180 | H7: 432506
B8: Financial assets at amortised cost – Debt and other financial instruments | C8: 6603815 | D8: 5337755 | E8: 6160065 | F8: 12188371 | G8: 24057370 | H8: 48296686
B9: Financial assets measured at fair value through other comprehensive income | C9: 15349974 | D9: 14478042 | E9: 15091368 | F9: 18053545 | G9: 22034788 | H9: 18995711
B11: From Bangladesh | C11: 1003916 | D11: 727417 | E11: 1318173 | F11: 1823578 | G11: 1419812 | H11: 3285610
B12: Securities purchased under resale agreements | C12: 57518 | D12: 85045 | E12: 277881 | F12: 218464 | G12: 12151 | H12: 919605
B13: Financial assets recognised through profit or loss | C13: 148381 | D13: 47875 | E13: 129265 | F13: 1133464 | G13: 515828 | H13: 846747
B14: Financial assets at amortised cost – Debt and other financial instruments | C14: 798017 | D14: 594497 | E14: 911027 | F14: 471650 | G14: 891833 | H14: 1519258
B16: Maldives
B17: Financial assets at amortised cost – Debt and other financial instruments | C17: 156598 | D17: 201931 | E17: 247379 | F17: 303081 | G17: 520270 | H17: 1226004
B19: Check | C19: =SUM(C6:C9)-C5+SUM(C12:C14)-C11 -> 0 | D19: =SUM(D6:D9)-D5+SUM(D12:D14)-D11 -> 0 | E19: =SUM(E6:E9)-E5+SUM(E12:E14)-E11 -> 0 | F19: =SUM(F6:F9)-F5+SUM(F12:F14)-F11 -> 0 | G19: =SUM(G6:G9)-G5+SUM(G12:G14)-G11 -> 0 | H19: =SUM(H6:H9)-H5+SUM(H12:H14)-H11 -> 0
B20: Check | C20: =(C8+C14+C17)-Drivers!C17 -> -953688 | D20: =(D8+D14+D17)-Drivers!D17 -> -694488 | E20: =(E8+E14+E17)-Drivers!E17 -> -501092 | F20: =(F8+F14+F17)-Drivers!F17 -> -231749 | G20: =(G8+G14+G17)-Drivers!G17 -> -481994 | H20: =(H8+H14+H17)-Drivers!H17 -> -708947
B31: GROSS loans and advances to other customers
B32: (LKR '000 except per share data) | C32: 2017 | D32: 2018 | E32: 2019 | F32: 2020 | G32: 2021 | H32: 2022
B33: By currency
B34: Sri Lankan Rupee | C34: 600058048 | D34: 692648484 | E34: 694387671 | F34: 714427226 | G34: 824624056 | H34: 842120414
B35: United States Dollar | C35: 113192698 | D35: 137588618 | E35: 152785345 | F35: 146750563 | G35: 169120449 | H35: 228254025
B36: Great Britain Pound | C36: 892245 | D36: 952806 | E36: 1297284 | F36: 1512981 | G36: 1369259 | H36: 2307564
B37: Euro | C37: 1500772 | D37: 1850804 | E37: 6671660 | F37: 9548883 | G37: 5507223 | H37: 6239416
B38: Australian Dollar | C38: 690992 | D38: 611436 | E38: 609115 | F38: 708584 | G38: 502605 | H38: 721089
B39: Japanese Yen | C39: 135765 | D39: 176039 | E39: 286695 | F39: 187489 | G39: 175531 | H39: 252705
B40: Singapore dollar | C40: 5504 | D40: 0 | E40: 2512 | F40: 0 | G40: 0 | H40: 0
B41: Bangladesh Taka | C41: 43164009 | D41: 62142187 | E41: 71252778 | F41: 84659542 | G41: 89272959 | H41: 157652152
B42: Maldivian Rufiyaa | C42: 737167 | D42: 1909104 | E42: 3141714 | F42: 3611052 | G42: 4074842 | H42: 8074579
B43: Others | C43: 76737 | D43: 76318 | E43: 302617 | F43: 452798 | G43: 283958 | H43: 548271
C44: =SUM(C34:C43) -> 760453937 | D44: =SUM(D34:D43) -> 897955796 | E44: =SUM(E34:E43) -> 930737391 | F44: =SUM(F34:F43) -> 961859118 | G44: =SUM(G34:G43) -> 1094930882 | H44: =SUM(H34:H43) -> 1246170215
B46: GROSS loans and advances to other customers
B47: By industry
B48: Agriculture and fishing | C48: 71041888 | D48: 84677466 | E48: 68775119 | F48: 78617259 | G48: 93304092 | H48: 126475449 | I48: =H48/$H$63 -> 0.10149131
B49: Arts, entertainment and recreation | D49: 949302 | E49: 1118938 | F49: 1288474 | G49: 1172974 | H49: 1488736 | I49: =H49/$H$63 -> 0.001194649
B50: Construction | C50: 106784977 | D50: 40689218 | E50: 45439269 | F50: 46454293 | G50: 56370508 | H50: 54627371 | I50: =H50/$H$63 -> 0.043836203
B51: Consumption and other | D51: 176273517 | E51: 201412039 | F51: 216286919 | G51: 168260117 | H51: 129274363 | I51: =H51/$H$63 -> 0.10373732
B52: Education | C52: 64040605 | D52: 2670021 | E52: 3225133 | F52: 3470636 | G52: 4295475 | H52: 3774937 | I52: =H52/$H$63 -> 0.0030292306
B53: Financial services | C53: 46764237 | D53: 40046006 | E53: 35777329 | F53: 36023186 | G53: 70326837 | H53: 95254707 | I53: =H53/$H$63 -> 0.076437958
B54: Healthcare, social services and support services | D54: 18546251 | E54: 18605625 | F54: 18480398 | G54: 26354594 | H54: 24631507 | I54: =H54/$H$63 -> 0.019765765
B55: Information technology and communication services | C55: 17479610 | D55: 12835806 | E55: 11403418 | F55: 11633615 | G55: 15155899 | H55: 17387197 | I55: =H55/$H$63 -> 0.013952506
B56: Infrastructure development | C56: 20886155 | D56: 19215514 | E56: 17083131 | F56: 17421563 | G56: 26786632 | H56: 33981732 | I56: =H56/$H$63 -> 0.027268933
...

Sheet COMB N
B2: COMB | F2: COMB
B3: Date | C3: Price to Book Ratio | F3: Date | G3: Last Price
B4: 45183 | C4: 0.5878 | F4: 45183 | G4: 93 | K4: Date | L4: Price Earnings Ratio (P/E)
B5: 45182 | C5: 0.584 | F5: 45182 | G5: 91.5 | K5: 45302 | L5: 5.1872 | W5: Date | X5: Price to Book Ratio
B6: 45181 | C6: 0.577 | F6: 45181 | G6: 90.4 | K6: 45301 | L6: 5.2719 | W6: 45302 | X6: 0.5642
B7: 45180 | C7: 0.5776 | F7: 45180 | G7: 90.5 | K7: 45300 | L7: 5.3284 | W7: 45301 | X7: 0.5734
B8: 45177 | C8: 0.5923 | F8: 45177 | G8: 92.8 | K8: 45299 | L8: 5.368 | W8: 45300 | X8: 0.5796
B9: 45176 | C9: 0.5878 | F9: 45176 | G9: 92.1 | K9: 45296 | L9: 5.3793 | W9: 45299 | X9: 0.5839
B10: 45175 | C10: 0.5885 | F10: 45175 | G10: 92.2 | K10: 45295 | L10: 5.3963 | W10: 45296 | X10: 0.5851
B11: 45174 | C11: 0.6063 | F11: 45174 | G11: 95 | K11: 45294 | L11: 5.4189 | W11: 45295 | X11: 0.587
B12: 45173 | C12: 0.5955 | F12: 45173 | G12: 93.3 | K12: 45293 | L12: 5.4754 | W12: 45294 | X12: 0.5894
B13: 45170 | C13: 0.5642 | F13: 45170 | G13: 88.4 | K13: 45289 | L13: 5.3963 | W13: 45293 | X13: 0.5956
B14: 45169 | C14: 0.5527 | F14: 45169 | G14: 86.6 | K14: 45288 | L14: 5.3284 | W14: 45289 | X14: 0.587
B15: 45167 | C15: 0.5553 | F15: 45167 | G15: 87 | K15: 45287 | L15: 5.2606 | W15: 45288 | X15: 0.5796
B16: 45166 | C16: 0.5553 | F16: 45166 | G16: 87 | K16: 45282 | L16: 5.2493 | W16: 45287 | X16: 0.5722
B17: 45163 | C17: 0.5553 | F17: 45163 | G17: 87 | K17: 45281 | L17: 5.2663 | W17: 45282 | X17: 0.571
... B53: 45112 | C53: 0.5189 | F53: 45112 | G53: 81.3 | K53: 45231 | L53: 4.7351 | W53: 45232 | X53: 0.5194
B54: 45111 | C54: 4.5982 | D54: 4.5982 | F54: 45111 | G54: 80.9 | K54: 45230 | L54: 4.6447 | W54: 45231 | X54: 0.5151
B55: 45105 | C55: 0.4346 | F55: 45105 | G55: 68.1 | K55: 45229 | L55: 4.6843 | W55: 45230 | X55: 0.5052
B56: 45104 | C56: 0.4091 | F56: 45104 | G56: 67.7 | K56: 45226 | L56: 4.6956 | W56: 45229 | X56: 0.5095
B57: 45103 | C57: 0.4128 | F57: 45103 | G57: 68.3 | K57: 45225 | L57: 4.6447 | W57: 45226 | X57: 0.5108
B58: 45100 | C58: 0.3995 | F58: 45100 | G58: 66.1 | K58: 45224 | L58: 4.6843 | W58: 45225 | X58: 0.5052
B59: 45099 | C59: 0.3995 | F59: 45099 | G59: 66.1 | K59: 45223 | L59: 4.7973 | W59: 45224 | X59: 0.5095
B60: 45098 | C60: 0.4001 | F60: 45098 | G60: 66.2 | K60: 45222 | L60: 4.9047 | W60: 45223 | X60: 0.5218
B61: 45097 | C61: 0.3868 | F61: 45097 | G61: 64 | K61: 45219 | L61: 4.9047 | W61: 45222 | X61: 0.5335
B62: 45096 | C62: 0.3928 | F62: 45096 | G62: 65 | K62: 45218 | L62: 4.6165 | W62: 45219 | X62: 0.5335
B63: 45093 | C63: 0.3989 | F63: 45093 | G63: 66 | K63: 45217 | L63: 4.5487 | W63: 45218 | X63: 0.5022
B64: 45092 | C64: 0.4007 | F64: 45092 | G64: 66.3 | K64: 45216 | L64: 4.5656 | W64: 45217 | X64: 0.4948
B65: 45091 | C65: 0.3928 | F65: 45091 | G65: 65 | K65: 45215 | L65: 4.543 | W65: 45216 | X65: 0.4966
B66: 45090 | C66: 0.3692 | F66: 45090 | G66: 61.1 | K66: 45212 | L66: 4.7464 | W66: 45215 | X66: 0.4942
... B1168: 43354 | C1168: 1.0884 | F1168: 43354 | G1168: 105.22 | K1168: 43476 | L1168: 7.187 | W1168: 43479 | X1168: 0.9667
B1169: 43353 | C1169: 1.0884 | F1169: 43353 | G1169: 105.22 | W1169: 43476 | X1169: 0.965
B1170: 43350 | C1170: 1.0964 | F1170: 43350 | G1170: 105.99
B1171: 43349 | C1171: 1.0946 | F1171: 43349 | G1171: 105.82
B1172: 43348 | C1172: 1.0946 | F1172: 43348 | G1172: 105.82
B1173: 43347 | C1173: 1.0928 | F1173: 43347 | G1173: 105.64
B1174: 43346 | C1174: 1.0973 | F1174: 43346 | G1174: 106.07

Sheet charts 1
B2: INCOME STATEMENT (LKR Mn except per sahre data) | C2: =FS!F4 -> 2020 | D2: =FS!G4 -> 2021 | E2: =FS!I4 -> 2022 | F2: =FS!J4 -> 2023F | G2: =FS!K4 -> 2024F | H2: =FS!L4 -> 2025F | L2: Key data | M2: COMB.N | N2: COMB.X | Q2: Key financials (LKR Mn) | R2: =C33 -> 2020 | S2: =D33 -> 2021 | T2: =E33 -> 2022 | U2: =F33 -> 2023F | V2: =G33 -> 2024F | W2: =H33 -> 2025F
B3: =FS!B6 -> Gross income | C3: =FS!F6/1000 -> 151966.41 | D3: =FS!G6/1000 -> 163675.31 | E3: =FS!I6/1000 -> 280386.94 | F3: =FS!J6/1000 -> 348708.88 | G3: =FS!K6/1000 -> 362864.83 | H3: =FS!L6/1000 -> 412721.43 | L3: Historical returns | Q3: Gross income | R3: =C3 -> 151966.41 | S3: =D3 -> 163675.31 | T3: =E3 -> 280386.94 | U3: =F3 -> 348708.88 | V3: =G3 -> 362864.83 | W3: =H3 -> 412721.43
B4: =FS!B7 -> Interest income | C4: =FS!F7/1000 -> 124087.71 | D4: =FS!G7/1000 -> 132818.18 | E4: =FS!I7/1000 -> 222393.08 | F4: =FS!J7/1000 -> 305857.34 | G4: =FS!K7/1000 -> 295139.36 | H4: =FS!L7/1000 -> 337849.48 | L4: 1-year capital gain | M4: =M18/M24-1 -> 0.79841897 | N4: =N18/N24-1 -> 0.90274314 | Q4: =B6 -> Net interest income | R4: =C6 -> 50868.802 | S4: =D6 -> 66416.332 | T4: =E6 -> 84665.211 | U4: =F6 -> 83162.406 | V4: =G6 -> 63118.873 | W4: =H6 -> 71691.068
B5: =FS!B8 -> Less: Interest expense | C5: =FS!F8/1000 -> 73218.911 | D5: =FS!G8/1000 -> 66401.846 | E5: =FS!I8/1000 -> 137727.87 | F5: =FS!J8/1000 -> 222694.93 | G5: =FS!K8/1000 -> 232020.49 | H5: =FS!L8/1000 -> 266158.41 | L5: 1-year dividend yield | M5: =M23/M24 -> 0.088932806 | N5: =N23/N24 -> 0.11221945 | Q5: =B27 -> Profit for the year | R5: =C30 -> 17086.797 | S5: =D30 -> 24290.288 | T5: =E30 -> 24399.472 | U5: =F30 -> 20621.731 | V5: =G30 -> 26844.366 | W5: =H30 -> 28592.935
B6: =FS!B9 -> Net interest income | C6: =FS!F9/1000 -> 50868.802 | D6: =FS!G9/1000 -> 66416.332 | E6: =FS!I9/1000 -> 84665.211 | F6: =FS!J9/1000 -> 83162.406 | G6: =FS!K9/1000 -> 63118.873 | H6: =FS!L9/1000 -> 71691.068 | L6: 1-year total return | M6: =M4+M5 -> 0.88735178 | N6: =N4+N5 -> 1.0149626 | Q6: Loans and advances | R6: =C38 -> 910608.88 | S6: =D38 -> 1029584.1 | T6: =E38 -> 1155492.5 | U6: =F38 -> 1214948.7 | V6: =G38 -> 1426353 | W6: =H38 -> 1651207.9
B7: =FS!B10 -> Fee and commission income | C7: =FS!F10/1000 -> 11839.689 | D7: =FS!G10/1000 -> 15917.337 | E7: =FS!I10/1000 -> 26191.53 | F7: =FS!J10/1000 -> 30373.717 | G7: =FS!K10/1000 -> 35658.826 | H7: =FS!L10/1000 -> 41280.198 | L7: Beta | M7: 0.78 | N7: 0.78 | Q7: =B44 -> Total assets | R7: =C44 -> 1762496.2 | S7: =D44 -> 1983491.1 | T7: =E44 -> 2499553.9 | U7: =F44 -> 2662322.4 | V7: =G44 -> 2953069.7 | W7: =H44 -> 3368903.3
B8: =FS!B11 -> Less: Fee and commission expense | C8: =FS!F11/1000 -> 2018.014 | D8: =FS!G11/1000 -> 3675.143 | E8: =FS!I11/1000 -> 6022.429 | F8: =FS!J11/1000 -> 7593.4292 | G8: =FS!K11/1000 -> 8201.5299 | H8: =FS!L11/1000 -> 9494.4454 | L8: 1-year high | M8: =MAX('Price volume'!$E$4:$E$248) -> 105 | N8: =MAX('Price volume'!$S$4:$S$248) -> 88.8 | Q8: EPS (LKR) | R8: =C31 -> 15.7 | S8: =D31 -> 19.41 | T8: =E31 -> 19.21 | U8: =F31 -> 15.064716 | V8: =G31 -> 19.610515 | W8: =H31 -> 20.88789
B9: =FS!B12 -> Net fee and commission income | C9: =FS!F12/1000 -> 9821.675 | D9: =FS!G12/1000 -> 12242.194 | E9: =FS!I12/1000 -> 20169.101 | F9: =FS!J12/1000 -> 22780.287 | G9: =FS!K12/1000 -> 27457.296 | H9: =FS!L12/1000 -> 31785.752 | L9: 1-year low | M9: =MIN('Price volume'!$E$4:$E$248) -> 50.2 | N9: =MIN('Price volume'!$S$4:$S$248) -> 40.1 | Q9: NAVPS (LKR) | R9: =C56 -> 136.42 | S9: =D56 -> 140.24 | T9: =E56 -> 168.47 | U9: =F56 -> 174.69072 | V9: =G56 -> 193.3115 | W9: =H56 -> 211.22648
B10: =FS!B13 -> Net gains/(losses) from trading | C10: =FS!F13/1000 -> 1878.06 | D10: =FS!G13/1000 -> 1936.007 | E10: =FS!I13/1000 -> 35297.45 | F10: =FS!J13/1000 -> -16199.576 | G10: =FS!K13/1000 -> 1955.3671 | H10: =FS!L13/1000 -> 1974.9207 | L10: Valuation multiples | Q10: Net margin | R10: =Ratios!F10 -> 0.11243798 | S10: =Ratios!G10 -> 0.14840533 | T10: =Ratios!H10 -> 0.087020714 | U10: =Ratios!I10 -> 0.059137383 | V10: =Ratios!J10 -> 0.073978971 | W10: =Ratios!K10 -> 0.069279017
B11: =FS!B14 -> Net gains/(losses) from derecognition of financial assets | C11: =FS!F14/1000 -> 6390.197 | D11: =FS!G14/1000 -> 3001.574 | E11: =FS!I14/1000 -> 276.884 | F11: =FS!J14/1000 -> 3517.6933 | G11: =FS!K14/1000 -> 3693.578 | H11: =FS!L14/1000 -> 3878.2569 | L11: PE ratio | M11: =M18/Valuation!$B$63 -> 5.2059497 | N11: =N18/Valuation!$B$63 -> 4.3649886 | Q11: ROE | R11: =Ratios!F11 -> 0.106163 | S11: =Ratios!G11 -> 0.14326114 | T11: =Ratios!H11 -> 0.11456626 | U11: =Ratios!I11 -> 0.087940259 | V11: =Ratios!J11 -> 0.10323137 | W11: =Ratios!K11 -> 0.1004223
B12: =FS!B15 -> Net other operating income | C12: =FS!F15/1000 -> 7770.754 | D12: =FS!G15/1000 -> 10002.216 | E12: =FS!I15/1000 -> -3771.999 | F12: =FS!J15/1000 -> 25159.709 | G12: =FS!K15/1000 -> 26417.695 | H12: =FS!L15/1000 -> 27738.58 | L12: PB ratio | M12: =M18/Valuation!$B$53 -> 0.55931162 | N12: =N18/Valuation!$B$53 -> 0.46896128 | Q12: ROA | R12: =Ratios!F12 -> 0.0096946578 | S12: =Ratios!G12 -> 0.01224623 | T12: =Ratios!H12 -> 0.0097615306 | U12: =Ratios!I12 -> 0.0077457677 | V12: =Ratios!J12 -> 0.009090326 | W12: =Ratios!K12 -> 0.0084873126
B13: =FS!B16 -> Total operating income | C13: =FS!F16/1000 -> 76729.488 | D13: =FS!G16/1000 -> 93598.323 | E13: =FS!I16/1000 -> 136636.65 | F13: =FS!J16/1000 -> 118420.52 | G13: =FS!K16/1000 -> 122642.81 | H13: =FS!L16/1000 -> 137068.58 | L13: Per share data
B14: =FS!B17 -> Less: Impairment charges and other losses | C14: =FS!F17/1000 -> 21419.532 | D14: =FS!G17/1000 -> 25139.926 | E14: =FS!I17/1000 -> 71924.26 | F14: =FS!J17/1000 -> 35328.926 | G14: =FS!K17/1000 -> 30095.011 | H14: =FS!L17/1000 -> 34609.262 | L14: EPS (TTM) (LKR) | M14: =Valuation!$B$63 -> 17.48 | N14: =Valuation!$B$63 -> 17.48
B15: =FS!B18 -> Net operating income | C15: =FS!F18/1000 -> 55309.956 | D15: =FS!G18/1000 -> 68458.397 | E15: =FS!I18/1000 -> 64712.387 | F15: =FS!J18/1000 -> 83091.594 | G15: =FS!K18/1000 -> 92547.798 | H15: =FS!L18/1000 -> 102459.31 | L15: NAVPS (Sep23) (LKR) | M15: =Valuation!$B$53 -> 162.7 | N15: =Valuation!$B$53 -> 162.7
B16: =FS!B19 -> Less: Expenses | L16: DPS (2023) | M16: =M23 -> 4.5 | N16: =N23 -> 4.5
B17: =FS!B20 -> Personnel expenses | C17: =FS!F20/1000 -> 14992.748 | D17: =FS!G20/1000 -> 16799.212 | E17: =FS!I20/1000 -> 19788.283 | F17: =FS!J20/1000 -> 21767.111 | G17: =FS!K20/1000 -> 23943.822 | H17: =FS!L20/1000 -> 26338.205
B18: =FS!B21 -> Depreciation and amortisation | C18: =FS!F21/1000 -> 3102.695 | D18: =FS!G21/1000 -> 3220.066 | E18: =FS!I21/1000 -> 3598.371 | F18: =FS!J21/1000 -> 4116.991 | G18: =FS!K21/1000 -> 4240.2272 | H18: =FS!L21/1000 -> 4381.8335 | L18: currrent price | M18: =Valuation!B97 -> 91 | N18: =Valuation!B102 -> 76.3
B19: =FS!B22 -> Other operating expenses | C19: =FS!F22/1000 -> 8167.17 | D19: =FS!G22/1000 -> 9638.461 | E19: =FS!I22/1000 -> 12895.587 | F19: =FS!J22/1000 -> 16764.263 | G19: =FS!K22/1000 -> 20117.116 | H19: =FS!L22/1000 -> 24140.539
B20: =FS!B23 -> Total operating expenses | C20: =FS!F23/1000 -> 26262.613 | D20: =FS!G23/1000 -> 29657.739 | E20: =FS!I23/1000 -> 36282.241 | F20: =FS!J23/1000 -> 42648.365 | G20: =FS!K23/1000 -> 48301.165 | H20: =FS!L23/1000 -> 54860.577 | L20: dividend
B21: =FS!B24 -> Operating profit before taxes on financial services | C21: =FS!F24/1000 -> 29047.343 | D21: =FS!G24/1000 -> 38800.658 | E21: =FS!I24/1000 -> 28430.146 | F21: =FS!J24/1000 -> 40443.229 | G21: =FS!K24/1000 -> 44246.633 | H21: =FS!L24/1000 -> 47598.738
B22: =FS!B25 -> Less: Taxes on financial services | C22: =FS!F25/1000 -> 4531.381 | D22: =FS!G25/1000 -> 5845.23 | E22: =FS!I25/1000 -> 3921.381 | F22: =FS!J25/1000 -> 4893.7174 | G22: =FS!K25/1000 -> 5902.7872 | H22: =FS!L25/1000 -> 6756.9895
B23: =FS!B26 -> Operating profit after taxes on financial services | C23: =FS!F26/1000 -> 24515.962 | D23: =FS!G26/1000 -> 32955.428 | E23: =FS!I26/1000 -> 24508.765 | F23: =FS!J26/1000 -> 35549.511 | G23: =FS!K26/1000 -> 38343.846 | H23: =FS!L26/1000 -> 40841.748 | L23: Scirpt dividend | M23: 4.5 | N23: 4.5
B24: =FS!B27 -> Share of profit/(loss) of associate, net of tax | C24: =FS!F27/1000 -> 3.898 | D24: =FS!G27/1000 -> 1.896 | E24: =FS!I27/1000 -> -3.727 | F24: =FS!J27/1000 -> 5.1973333 | G24: =FS!K27/1000 -> 5.2493067 | H24: =FS!L27/1000 -> 5.3017997 | L24: 1-year ago price | M24: ='Price volume'!$E$248 -> 50.6 | N24: ='Price volume'!$S$248 -> 40.1
B25: =FS!B28 -> Profit before tax | C25: =FS!F28/1000 -> 24519.86 | D25: =FS!G28/1000 -> 32957.324 | E25: =FS!I28/1000 -> 24505.038 | F25: =FS!J28/1000 -> 35554.709 | G25: =FS!K28/1000 -> 38349.095 | H25: =FS!L28/1000 -> 40847.05
B26: =FS!B29 -> Less: Income tax expense/(reversal) | C26: =FS!F29/1000 -> 7433.063 | D26: =FS!G29/1000 -> 8667.036 | E26: =FS!I29/1000 -> 105.566 | F26: =FS!J29/1000 -> 14932.978 | G26: =FS!K29/1000 -> 11504.728 | H26: =FS!L29/1000 -> 12254.115
B27: =FS!B30 -> Profit for the year | C27: =FS!F30/1000 -> 17086.797 | D27: =FS!G30/1000 -> 24290.288 | E27: =FS!I30/1000 -> 24399.472 | F27: =FS!J30/1000 -> 20621.731 | G27: =FS!K30/1000 -> 26844.366 | H27: =FS!L30/1000 -> 28592.935
B28: =FS!B31 -> Profit attributable to: Equity holders of the Bank | C28: =FS!F31/1000 -> 16939.95 | D28: =FS!G31/1000 -> 24062.469 | E28: =FS!I31/1000 -> 23811.914 | F28: =FS!J31/1000 -> 19796.862 | G28: =FS!K31/1000 -> 25770.592 | H28: =FS!L31/1000 -> 27449.218 | L28: Shareholding details
B29: =FS!B32 -> Non-controlling interest | C29: =FS!F32/1000 -> 146.847 | D29: =FS!G32/1000 -> 227.819 | E29: =FS!I32/1000 -> 587.558 | F29: =FS!J32/1000 -> 824.86924 | G29: =FS!K32/1000 -> 1073.7747 | H29: =FS!L32/1000 -> 1143.7174 | L29: No of shares (Mn)-voting | N29: =Drivers!I570/1000000 -> 1236.5254
B30: =FS!B33 -> Profit for the year | C30: =FS!F33/1000 -> 17086.797 | D30: =FS!G33/1000 -> 24290.288 | E30: =FS!I33/1000 -> 24399.472 | F30: =FS!J33/1000 -> 20621.731 | G30: =FS!K33/1000 -> 26844.366 | H30: =FS!L33/1000 -> 28592.935 | L30: No of shares (Mn)-non voting | N30: =Drivers!I578/1000000 -> 77.595733
B31: Earnings Per Share (LKR) | C31: =FS!F34 -> 15.7 | D31: =FS!G34 -> 19.41 | E31: =FS!I34 -> 19.21 | F31: =FS!J34 -> 15.064716 | G31: =FS!K34 -> 19.610515 | H31: =FS!L34 -> 20.88789 | L31: Total no of shares (Mn) | N31: =N29+N30 -> 1314.1211
L32: MCAP (Mn)-voting | N32: 113884
B33: BALANCE SHEET (LKR Mn except per sahre data) | C33: =C2 -> 2020 | D33: =D2 -> 2021 | E33: =E2 -> 2022 | F33: =F2 -> 2023F | G33: =G2 -> 2024F | H33: =H2 -> 2025F | L33: MCAP (Mn)-non voting | N33: 6161
B34: Assets | L34: Public holding-voting | N34: 0.9981
B35: Cash and cash equivalents | C35: =FS!F45/1000 -> 51255.03 | D35: =FS!G45/1000 -> 69335.379 | E35: =FS!I45/1000 -> 151109.49 | F35: =FS!J45/1000 -> 105916.32 | G35: =FS!K45/1000 -> 109690.08 | H35: =FS!L45/1000 -> 159083.79 | L35: Public holding-non voting | N35: 0.9988
B36: Balances with banks and derivatives | C36: =(FS!F46+FS!F47+FS!F48+FS!F49)/1000 -> 134417.32 | D36: =(FS!G46+FS!G47+FS!G48+FS!G49)/1000 -> 75521.784 | E36: =(FS!I46+FS!I47+FS!I48+FS!I49)/1000 -> 184542.46 | F36: =(FS!J46+FS!J47+FS!J48+FS!J49)/1000 -> 135653.99 | G36: =(FS!K46+FS!K47+FS!K48+FS!K49)/1000 -> 182279.86 | H36: =(FS!L46+FS!L47+FS!L48+FS!L49)/1000 -> 200873.78 | L36: Top 5 shareholders - COMB.N
B37: Financial assets through profit or loss (fair value) | C37: =FS!F50/1000 -> 35189.471 | D37: =FS!G50/1000 -> 23436.123 | E37: =FS!I50/1000 -> 24873.057 | F37: =FS!J50/1000 -> 98932.873 | G37: =FS!K50/1000 -> 155960.06 | H37: =FS!L50/1000 -> 171556.07 | L37: DFCC Bank PLC A/C 1 | N37: 0.1211
B38: Loans and advances to other customers | C38: =(FS!F52+FS!F51)/1000 -> 910608.88 | D38: =(FS!G52+FS!G51)/1000 -> 1029584.1 | E38: =(FS!I52+FS!I51)/1000 -> 1155492.5 | F38: =(FS!J52+FS!J51)/1000 -> 1214948.7 | G38: =(FS!K52+FS!K51)/1000 -> 1426353 | H38: =(FS!L52+FS!L51)/1000 -> 1651207.9 | L38: Mr.Y. S. H. I. Silva | N38: 0.0989
B39: Debt and other financial instruments | C39: =FS!F53/1000 -> 302059.53 | D39: =FS!G53/1000 -> 385390.6 | E39: =FS!I53/1000 -> 761650.23 | F39: =FS!J53/1000 -> 709291.12 | G39: =FS!K53/1000 -> 668358.32 | H39: =FS!L53/1000 -> 737754.18 | L39: Employees' Provident Fund | N39: 0.0861
B40: Financial assets through other comprehensive income | C40: =FS!F54/1000 -> 278716.79 | D40: =FS!G54/1000 -> 335953.8 | E40: =FS!I54/1000 -> 118652.26 | F40: =FS!J54/1000 -> 296954.73 | G40: =FS!K54/1000 -> 326650.2 | H40: =FS!L54/1000 -> 359315.22 | L40: Mr. D. P. Pieris | N40: 0.0771
B41: Investment in associate | C41: =(FS!F55+FS!F56)/1000 -> 64.155 | D41: =(FS!G55+FS!G56)/1000 -> 60.428 | E41: =(FS!I55+FS!I56)/1000 -> 55.302 | F41: =(FS!J55+FS!J56)/1000 -> 55.302 | G41: =(FS!K55+FS!K56)/1000 -> 55.302 | H41: =(FS!L55+FS!L56)/1000 -> 55.302 | L41: Int. Finance Corporation | N41: 0.0711
...

Sheet chart 2
C4: LKR Bn | D4: 2019 | E4: =D4+1 -> 2020 | F4: =E4+1 -> 2021 | G4: =F4+1 -> 2022 | H4: =FS!J4 -> 2023F | I4: =FS!K4 -> 2024F | J4: =FS!L4 -> 2025F | K4: =FS!M4 -> 2026F
C5: Loans and advanves to customers (LHS) (LKR Bn) | D5: =FS!E52/1000000 -> 893.91931 | E5: =FS!F52/1000000 -> 909.82917 | F5: =FS!G52/1000000 -> 1029.5841 | G5: =FS!I52/1000000 -> 1155.4925 | H5: =FS!J52/1000000 -> 1214.9487 | I5: =FS!K52/1000000 -> 1426.353 | J5: =FS!L52/1000000 -> 1651.2079 | K5: =FS!M52/1000000 -> 1908.0432
C6: Growth YoY (%) (RHS) | D6: =FS!E52/FS!D52-1 -> 0.030321544 | E6: =FS!F52/FS!E52-1 -> 0.017797871 | F6: =FS!G52/FS!F52-1 -> 0.1316235 | G6: =FS!I52/FS!G52-1 -> 0.1222906 | H6: =FS!J52/FS!I52-1 -> 0.051455235 | I6: =FS!K52/FS!J52-1 -> 0.17400271 | J6: =FS!L52/FS!K52-1 -> 0.15764321 | K6: =FS!M52/FS!L52-1 -> 0.15554391
E26: SDFR | F26: SLFR | L26: AWPR | M26: AWDR | N26: Spread
C27: 2019 | D27: 43466 | E27: 0.08 | F27: 0.09 | K27: 43466 | L27: 0.1205 | M27: 0.0885 | N27: =L27-M27 -> 0.032
D28: 43497 | E28: 0.08 | F28: 0.09 | K28: 43497 | L28: 0.123 | M28: 0.0888 | N28: =L28-M28 -> 0.0342
D29: 43525 | E29: 0.08 | F29: 0.09 | K29: 43525 | L29: 0.1223 | M29: 0.0898 | N29: =L29-M29 -> 0.0325
D30: 43556 | E30: 0.08 | F30: 0.09 | K30: 43556 | L30: 0.1207 | M30: 0.0897 | N30: =L30-M30 -> 0.031
D31: 43586 | E31: 0.075 | F31: 0.085 | K31: 43586 | L31: 0.1201 | M31: 0.09 | N31: =L31-M31 -> 0.0301
D32: 43617 | E32: 0.075 | F32: 0.085 | K32: 43617 | L32: 0.1145 | M32: 0.0894 | N32: =L32-M32 -> 0.0251
D33: 43647 | E33: 0.075 | F33: 0.085 | K33: 43647 | L33: 0.1093 | M33: 0.0888 | N33: =L33-M33 -> 0.0205
D34: 43678 | E34: 0.07 | F34: 0.08 | K34: 43678 | L34: 0.1069 | M34: 0.0873 | N34: =L34-M34 -> 0.0196
D35: 43709 | E35: 0.07 | F35: 0.08 | K35: 43709 | L35: 0.1057 | M35: 0.0851 | N35: =L35-M35 -> 0.0206
D36: 43739 | E36: 0.07 | F36: 0.08 | K36: 43739 | L36: 0.1042 | M36: 0.0837 | N36: =L36-M36 -> 0.0205
D37: 43770 | E37: 0.07 | F37: 0.08 | K37: 43770 | L37: 0.1021 | M37: 0.0827 | N37: =L37-M37 -> 0.0194
D38: 43800 | E38: 0.07 | F38: 0.08 | K38: 43800 | L38: 0.1 | M38: 0.082 | N38: =L38-M38 -> 0.018
C39: 2020 | D39: 43831 | E39: 0.065 | F39: 0.075 | K39: 43831 | L39: 0.0968 | M39: 0.0814 | N39: =L39-M39 -> 0.0154
D40: 43862 | E40: 0.065 | F40: 0.075 | K40: 43862 | L40: 0.0951 | M40: 0.0806 | N40: =L40-M40 -> 0.0145
D41: 43891 | E41: 0.0625 | F41: 0.0725 | K41: 43891 | L41: 0.0935 | M41: 0.079 | N41: =L41-M41 -> 0.0145
D42: 43922 | E42: 0.06 | F42: 0.07 | K42: 43922 | L42: 0.0938 | M42: 0.0777 | N42: =L42-M42 -> 0.0161
D43: 43952 | E43: 0.055 | F43: 0.065 | K43: 43952 | L43: 0.0928 | M43: 0.0757 | N43: =L43-M43 -> 0.0171
D44: 43983 | E44: 0.055 | F44: 0.065 | K44: 43983 | L44: 0.0878 | M44: 0.0738 | N44: =L44-M44 -> 0.014
D45: 44013 | E45: 0.045 | F45: 0.055 | K45: 44013 | L45: 0.0779 | M45: 0.0716 | N45: =L45-M45 -> 0.0063
D46: 44044 | E46: 0.045 | F46: 0.055 | K46: 44044 | L46: 0.0701 | M46: 0.0674 | N46: =L46-M46 -> 0.0027
D47: 44075 | E47: 0.045 | F47: 0.055 | K47: 44075 | L47: 0.0642 | M47: 0.0644 | N47: =L47-M47 -> -0.0002
D48: 44105 | E48: 0.045 | F48: 0.055 | K48: 44105 | L48: 0.061 | M48: 0.0623 | N48: =L48-M48 -> -0.0013
D49: 44136 | E49: 0.045 | F49: 0.055 | K49: 44136 | L49: 0.0595 | M49: 0.0601 | N49: =L49-M49 -> -0.0006
D50: 44166 | E50: 0.045 | F50: 0.055 | K50: 44166 | L50: 0.0574 | M50: 0.058 | N50: =L50-M50 -> -0.0006
C51: 2021 | D51: 44197 | E51: 0.045 | F51: 0.055 | K51: 44197 | L51: 0.0582 | M51: 0.0558 | N51: =L51-M51 -> 0.0024
D52: 44228 | E52: 0.045 | F52: 0.055 | K52: 44228 | L52: 0.0572 | M52: 0.0536 | N52: =L52-M52 -> 0.0036
D53: 44256 | E53: 0.045 | F53: 0.055 | K53: 44256 | L53: 0.0567 | M53: 0.052 | N53: =L53-M53 -> 0.0047
D54: 44287 | E54: 0.045 | F54: 0.055 | K54: 44287 | L54: 0.0565 | M54: 0.0507 | N54: =L54-M54 -> 0.0058
D55: 44317 | E55: 0.045 | F55: 0.055 | K55: 44317 | L55: 0.0569 | M55: 0.0497 | N55: =L55-M55 -> 0.0072
D56: 44348 | E56: 0.045 | F56: 0.055 | K56: 44348 | L56: 0.0567 | M56: 0.0487 | N56: =L56-M56 -> 0.008
D57: 44378 | E57: 0.045 | F57: 0.055 | K57: 44378 | L57: 0.05695 | M57: 0.0477 | N57: =L57-M57 -> 0.00925
D58: 44409 | E58: 0.05 | F58: 0.06 | K58: 44409 | L58: 0.0585 | M58: 0.0475 | N58: =L58-M58 -> 0.011
