Workbook

Sheet Cover
B3: Commercial Bank of Ceylon PLC
B4: COMB N
B5: COMB X

Sheet FS
B3: For the year ended December 31,
B4: (LKR '000 except per share data) | C4: 2017 | D4: 2018 | E4: 2019 | F4: 2020 | G4: 2021 | H4: 2022 | I4: 2023 | J4: 2024 | K4: 2025
B5: INCOME STATEMENT
B6: Gross income | C6: 116841755 | D6: - | E6: 150741129 | F6: 151966413 | G6: 163675312 | H6: 280386944 | I6: 341566200 | J6: 274975814 | K6: 365180892
B7: Interest income | C7: 104049102 | D7: - | E7: 129287473 | F7: 124087713 | G7: 132818178 | H7: 222393079 | I7: 297645866 | J7: 275217117 | K7: 301366595
B8: Less: Interest expense | C8: 64481004 | D8: - | E8: 80931352 | F8: 73218911 | G8: 66401846 | H8: 137727868 | I8: 211230507 | J8: 157082433 | K8: 160406053
B9: Net interest income | C9: 39567298 | D9: - | E9: 48356391 | F9: 50868802 | G9: 66416332 | H9: 84665211 | I9: 86415359 | J9: 118134684 | K9: 140960542
B10: Fee and commission income | C10: 10510800 | D10: - | E10: 12874966 | F10: 11839689 | G10: 15917337 | H10: 26191530 | I10: 30653212 | J10: 34480523 | K10: 42592091
B11: Less: Fee and commission expense | C11: 1586334 | D11: - | E11: 2123128 | F11: 2018014 | G11: 3675143 | H11: 6022429 | I11: 8265893 | J11: 10834345 | K11: 13616570
B12: Net fee and commission income | C12: 8924466 | D12: - | E12: 10751838 | F12: 9821675 | G12: 12242194 | H12: 20169101 | I12: 22387319 | J12: 23646178 | K12: 28975521
B13: Net gains/(losses) from trading | C13: 233956 | D13: - | E13: 1360833 | F13: 1878060 | G13: 1936007 | H13: 35297450 | I13: -12481613 | J13: -2201010 | K13: 344
B14: Net gains/(losses) from derecognition of financial assets | C14: 129210 | D14: - | E14: 1135711 | F14: 6390197 | G14: 3001574 | H14: 276884 | I14: 5060242 | J14: -41016836 | K14: 344
B15: Net other operating income | C15: 1918687 | D15: - | E15: 6081876 | F15: 7770754 | G15: 10002216 | H15: -3771999 | I15: 20688493 | J15: 8496020 | K15: 345
B16: Total operating income | C16: 50773617 | D16: - | E16: 67686649 | F16: 67686649 | G16: 93598323 | H16: 136636647 | I16: 122069800 | J16: 107059326 | K16: 191158269
B17: Less: Impairment charges and other losses | C17: 2225914 | D17: -4413 | E17: 11331525 | F17: 21419532 | G17: 25139926 | H17: 71924260 | I17: 38095070 | J17: - | K17: -
B18: Net operating income | C18: 48547703 | D18: - | E18: 56355126 | F18: 56355126 | G18: 68458397 | H18: 64712387 | I18: 83174730 | J18: 169353580 | K18: 168041772
B19: Less: Expenses
B20: Personnel expenses | C20: 11338517 | D20: - | E20: 14008914 | F20: 14992748 | G20: 16799212 | H20: 19788283 | I20: 22824913 | J20: 27907458 | K20: 349
B21: Depreciation and amortisation | C21: 1416927 | D21: - | E21: 2841264 | F21: 3102695 | G21: 3220066 | H21: 3598371 | I21: 4335640 | J21: 4737203 | K21: 350
B22: Other operating expenses | C22: 7618993 | D22: - | E22: 8875316 | F22: 8167170 | G22: 9638461 | H22: 12895587 | I22: 17129279 | J22: 19193697 | K22: 351
B23: Total operating expenses | C23: 20374437 | D23: - | E23: 26125494 | F23: 26125494 | G23: 29657739 | H23: 36282241 | I23: - | J23: 51838358 | K23: 57502998
B24: Operating profit before taxes on financial services | C24: 23280324 | D24: - | E24: 30229632 | F24: 30229632 | G24: 32957324 | H24: 28430146 | I24: 38884898 | J24: 117515492 | K24: 110538774
B25: Less: Taxes on financial services | C25: 4896620 | D25: - | E25: 7255728 | F25: 4531381 | G25: 5845230 | H25: 3921381 | I25: 4961392 | J25: 19706675 | K25: 351
B26: Operating profit after taxes on financial services | C26: 23276646 | D26: - | E26: 22973904 | F26: 22973904 | G26: 32955428 | H26: 24508765 | I26: 33923506 | J26: 97808817 | K26: 92788083
B27: Share of profit/(loss) of associate, net of tax | C27: 3678 | D27: - | E27: 9992 | F27: - | G27: - | H27: -3727 | I27: 3495 | J27: -460 | K27: 379
B28: Profit before tax | C28: 23280324 | D28: 12056211 | E28: 22983896 | F28: 22983896 | G28: 32957324 | H28: 24505038 | I28: 38884898 | J28: 97808357 | K28: 92787421
B29: Less: Income tax expense/(reversal) | C29: 6653817 | D29: - | E29: 5563500 | F29: 7433063 | G29: 8667036 | H29: 105566 | I29: 12027341 | J29: 42121945 | K29: 352
B30: Profit for the year | C30: 16626507 | D30: - | E30: 17420396 | F30: 17420396 | G30: 24290288 | H30: 24399472 | I30: 21899660 | J30: 55686412 | K30: 60937517
B31: Profit attributable to: Equity holders of the Bank | C31: 16605963 | D31: - | E31: 17263259 | F31: 17263259 | G31: 24062469 | H31: 23811914 | I31: 21114675 | J31: 55073240 | K31: 60110183
B32: Non-controlling interest | C32: 20544 | D32: - | E32: 157137 | F32: 157137 | G32: 227819 | H32: 587558 | I32: 784985 | J32: 613172 | K32: 827334
B33: Profit for the year | C33: 16626507 | D33: - | E33: 17420396 | F33: 17420396 | G33: 24290288 | H33: 24399472 | I33: 21899660 | J33: 55686412 | K33: 60937517
B34: Earnings per share Basic earnings per ordinary share (Rs.) | C34: 17.28 | D34: - | E34: 16.8 | F34: 15.7 | G34: 20.15 | H34: 19.21 | I34: 16.07 | J34: 38.44 | K34: 353
B35: Diluted earnings per ordinary share (Rs.) | C35: 17.27 | D35: - | E35: 16.8 | F35: 15.7 | G35: 20.15 | H35: 19.21 | I35: 16.06 | J35: 38.38 | K35: 353
B36: Diviend per share | C36: - | D36: - | E36: - | F36: - | G36: - | H36: - | I36: - | J36: - | K36: -
B38: OCI
B39: Transfer of FV losses reclassification of debt from FVTOCI to AC | C39: - | D39: - | E39: - | F39: - | G39: - | H39: - | I39: - | J39: - | K39: -
B41: IS check | C41: =IF(C18-C23-C25+C27-C29-C30+C31+C32-C33=0,"OK","FLAG") | D41: =IF(D18-D23-D25+D27-D29-D30+D31+D32-D33=0,"OK","FLAG") | E41: =IF(E18-E23-E25+E27-E29-E30+E31+E32-E33=0,"OK","FLAG") | F41: =IF(F18-F23-F25+F27-F29-F30+F31+F32-F33=0,"OK","FLAG") | G41: =IF(G18-G23-G25+G27-G29-G30+G31+G32-G33=0,"OK","FLAG") | H41: =IF(H18-H23-H25+H27-H29-H30+H31+H32-H33=0,"OK","FLAG") | I41: =I18-I23-I25+I27-I29-I30+I31+I32-I33 | J41: =J18-J23-J25+J27-J29-J30+J31+J32-J33 | K41: =K18-K23-K25+K27-K29-K30+K31+K32-K33
B43: BALANCE SHEET
B44: Assets
B45: Cash and cash equivalents | C45: 3031093 | D45: 44355962 | E45: 53681118 | F45: 50250627 | G45: 69335379 | H45: 149393561 | I45: 159701507 | J45: 86848291 | K45: 88857011
...

Sheet Drivers
B3: For the year ended December 31,
B4: (LKR '000 except per share data) | C4: 2017 | D4: 2018 | E4: 2019 | F4: 2020 | G4: 2021 | H4: 2022 | I4: 2023 | J4: 2024 | K4: 2025
B5: INCOME STATEMENT
B7: Interest income | C7: 104049102 | D7: - | E7: 129287473 | F7: 124087713 | G7: 132818178 | H7: 222393079 | I7: - | J7: 275217117 | K7: 301366595
B9: Cash and cash equivalents | C9: 3031093 | D9: 44355962 | E9: 53681118 | F9: 50250627 | G9: 69335379 | H9: 149393561 | I9: 159701507 | J9: 86848291 | K9: 88857011
B10: Balances with Central Banks | C10: - | D10: 55605535 | E10: 46101232 | F10: 110971105 | G10: 241 | H10: 66439459 | I10: 621633503 | J10: 45270068 | K10: 47809989
B11: Placements with Banks | C11: - | D11: 23989815 | E11: 24203909 | F11: -34.06 | G11: 241 | H11: 95899645 | I11: 81506653 | J11: 99303303 | K11: 110223171
B12: Securities purchased under resale agreements | C12: 57518 | D12: 9513512 | E12: 13147584 | F12: 13147534 | G12: 3000490 | H12: 1517308 | I12: 31138729 | J12: 28655962 | K12: 17446102
B13: Financial assets recognized through profit or loss | C13: - | D13: - | E13: - | F13: - | G13: - | H13: - | I13: - | J13: - | K13: -
B14: Derivatives | C14: - | D14: - | E14: - | F14: - | G14: - | H14: - | I14: - | J14: - | K14: -
B15: Other financial instruments | C15: 156598 | D15: 89274113 | E15: 247379 | F15: 182.14 | G15: 250 | H15: 725935929 | I15: 685155537 | J15: 667709691 | K15: 731263697
B16: Financial assets at amortized cost - loans and advances to other customers | C16: - | D16: - | E16: 893919311 | F16: - | G16: - | H16: - | I16: - | J16: 1384524660 | K16: 1958506596
B17: Financial assets at amortized cost - debt and other financial instruments | C17: - | D17: - | E17: - | F17: - | G17: - | H17: - | I17: - | J17: - | K17: -
B18: Financial assets measured at fair value through other comprehensive income | C18: 15349974 | D18: 176760611 | E18: 197825017 | F18: 278461369 | G18: 251 | H18: 117056240 | I18: 287732972 | J18: 4090697 | K18: 2911061462
B19: Interest accrued on impaired loans and advances to other customers | C19: - | D19: - | E19: 893919311 | F19: - | G19: - | H19: - | I19: - | J19: 1384524660 | K19: 1958506596
C20: 2413 | D20: 2661 | E20: 7884 | F20: 11375 | G20: 0 | H20: 0
B22: Check | C22: -857269981 | D22: -994370875 | E22: -1068982587 | F22: -1286616399 | G22: 0 | H22: 0 | I22: - | J22: - | K22: -
B24: Interest rate | C24: - | D24: - | E24: - | F24: - | G24: - | H24: - | I24: - | J24: - | K24: -
B26: Cash and cash equivalents | C26: 3031093 | D26: 44355962 | E26: 53681118 | F26: 50250627 | G26: 69335379 | H26: 149393561 | I26: 159701507 | J26: 86848291 | K26: 88857011
B27: Balances with Central Banks | C27: - | D27: 55605535 | E27: 46101232 | F27: 110971105 | G27: 241 | H27: 66439459 | I27: 621633503 | J27: 45270068 | K27: 47809989
B28: Placements with Banks | C28: - | D28: 23989815 | E28: 24203909 | F28: -34.06 | G28: 241 | H28: 95899645 | I28: 81506653 | J28: 99303303 | K28: 110223171
B29: Securities purchased under resale agreements | C29: 57518 | D29: 9513512 | E29: 13147584 | F29: 13147534 | G29: 3000490 | H29: 1517308 | I29: 31138729 | J29: 28655962 | K29: 17446102
B30: Financial assets recognized through profit or loss | C30: - | D30: - | E30: - | F30: - | G30: - | H30: - | I30: - | J30: - | K30: -
B31: Derivatives | C31: - | D31: - | E31: - | F31: - | G31: - | H31: - | I31: - | J31: - | K31: -
B32: Other financial instruments | C32: 156598 | D32: 89274113 | E32: 247379 | F32: 182.14 | G32: 250 | H32: 725935929 | I32: 685155537 | J32: 667709691 | K32: 731263697
B33: Financial assets at amortized cost - loans and advances to other customers | C33: - | D33: - | E33: 893919311 | F33: - | G33: - | H33: - | I33: - | J33: 1384524660 | K33: 1958506596
B34: Overdrafts | C34: - | D34: - | E34: - | F34: - | G34: - | H34: - | I34: - | J34: - | K34: -
B35: Trade finance | C35: - | D35: - | E35: - | F35: - | G35: - | H35: - | I35: - | J35: - | K35: -
B36: Lease/hire purchase receivable | C36: - | D36: - | E36: - | F36: - | G36: - | H36: - | I36: - | J36: - | K36: -
B37: Credit cards | C37: - | D37: - | E37: - | F37: - | G37: - | H37: - | I37: - | J37: - | K37: -
B38: Pawning | C38: - | D38: - | E38: - | F38: - | G38: - | H38: - | I38: - | J38: - | K38: -
B39: Staff loans | C39: - | D39: - | E39: - | F39: - | G39: - | H39: - | I39: - | J39: - | K39: -
B40: Housing loans | C40: - | D40: - | E40: - | F40: - | G40: - | H40: - | I40: - | J40: - | K40: -
B41: Personal loans | C41: - | D41: - | E41: - | F41: - | G41: - | H41: - | I41: - | J41: - | K41: -
B42: Term loans | C42: - | D42: - | E42: - | F42: - | G42: - | H42: - | I42: - | J42: - | K42: -
B43: Short term | C43: - | D43: - | E43: - | F43: - | G43: - | H43: - | I43: - | J43: - | K43: -
B44: Long term | C44: - | D44: - | E44: - | F44: - | G44: - | H44: - | I44: - | J44: - | K44: -
B45: Bills of exchange | C45: - | D45: - | E45: - | F45: - | G45: - | H45: - | I45: - | J45: - | K45: -
... B50: Financial assets at amortized cost - debt and other financial instruments | C50: - | D50: - | E50: - | F50: - | G50: - | H50: - | I50: - | J50: - | K50: -
B52: Financial assets measured at fair value through other comprehensive income | C52: 15349974 | D52: 176760611 | E52: 197825017 | F52: 278461369 | G52: 251 | H52: 117056240 | I52: 287732972 | J52: 4090697 | K52: 2911061462
...

Sheet Ratios
C2: =FS!C4 | D2: =FS!D4 | E2: =FS!E4 | F2: =FS!F4 | G2: =FS!G4 | H2: =FS!H4 | I2: =FS!I4 | J2: =FS!J4 | K2: =FS!K4
B3: Avg. yield on interest earning assets | C3: - | D3: - | E3: 0.1046999 | F3: 0.44561866 | G3: 89985.215 | H3: 0.11082788 | I3: 0.13616474 | J3: 0.13297076 | K3: 0.052704821
B4: Avg. cost on interest bearing funds | C4: - | D4: - | E4: - | F4: 18.547308 | G4: - | H4: 0.065702149 | I4: 0.093523009 | J4: - | K4: 0.058022545
B5: Net interest margin | C5: - | D5: - | E5: 0.039160094 | F5: 0.18267794 | G5: 44997.515 | H5: 0.042192255 | I5: 0.039532634 | J5: 0.057076605 | K5: 0.024652036
B6: Interest rate spread | C6: - | D6: - | E6: - | F6: -18.101689 | G6: - | H6: 0.045125727 | I6: 0.042641733 | J6: - | K6: -0.0053177242
B7: Cost to income (operating) | C7: 0.40128 | D7: - | E7: 0.38597706 | F7: 0.38597706 | G7: 0.31686186 | H7: 0.26553814 | I7: - | J7: 0.48420217 | K7: 0.30081355
B8: Cost to income (with impairments) | C8: 0.19342701 | D8: - | E8: 0.24848573 | F8: 0.31286536 | G8: 0.33479493 | H8: 0.38591847 | I8: 0.11153056 | J8: 0.1885197 | K8: 0.15746442
B9: Impairments/ Gross loans | C9: - | D9: -5.0863752e-06 | E9: 0.012676228 | F9: 12101431 | G9: 102194.82 | H9: 0.063624868 | I9: 0.032383854 | J9: - | K9: -
B10: Net margin | C10: 0.14229936 | D10: - | E10: 0.11556498 | F10: 0.1146332 | G10: 0.14840533 | H10: 0.087020714 | I10: 0.064115419 | J10: 0.20251385 | K10: 0.1668694
B11: ROE | C11: 0.15272344 | D11: - | E11: - | F11: 0.11085476 | G11: - | H11: 0.11978437 | I11: 0.10189158 | J11: - | K11: 0.13687137
B12: ROA | C12: - | D12: - | E12: 0.016607597 | F12: 0.01003353 | G12: 0.0122487 | H12: 0.010058345 | I12: 0.0082465596 | J12: 0.019960856 | K12: 0.018035007
B13: Equity/ total assets | C13: - | D13: - | E13: - | F13: 0.090510595 | G13: - | H13: 0.083970426 | I13: 0.080934649 | J13: - | K13: 0.1317661
B14: Deposits / total assets | C14: - | D14: - | E14: - | F14: 1.1726638e-08 | G14: - | H14: 0.78916802 | I14: 0.78514717 | J14: - | K14: 0.77211323
B15: Cash / total assets | C15: - | D15: 0.033605236 | E15: 0.051176472 | F15: 0.028942579 | G15: 0.034963284 | H15: 0.061585429 | I15: 0.060137372 | J15: 0.031130865 | K15: 0.026298032
B16: Gross income per employee | C16: - | D16: - | E16: - | F16: 30050.705 | G16: - | H16: 54752.381 | I16: - | J16: - | K16: -
B17: Dividend payout | C17: - | D17: - | E17: - | F17: - | G17: - | H17: 0.23425299 | I17: - | J17: - | K17: -
B18: Gross income per service centre | C18: - | D18: - | E18: - | F18: 529499.7 | G18: - | H18: 970197.04 | I18: - | J18: - | K18: -
B19: Net interest spread | C19: - | D19: - | E19: - | F19: -18.101689 | G19: - | H19: 0.045125727 | I19: 0.042641733 | J19: - | K19: -0.0053177242
B20: Gross income per service centre | C20: =FS!C6/FS!C88 | D20: =FS!D6/FS!D88 | E20: =FS!E6/FS!E88 | F20: =FS!F6/FS!F88 | G20: =FS!G6/FS!G88 | H20: =FS!H6/FS!H88 | I20: =FS!I6/FS!I88 | J20: =FS!J6/FS!J88 | K20: =FS!K6/FS!K88
B22: Net interest spread | F22: =F3-F4 | G22: =G3-G4 | H22: =H3-H4 | I22: =I3-I4 | J22: =J3-J4 | K22: =K3-K4

Sheet Quarterly
C1: For the quarter ended
C2: Mar 2017 | D2: Jun 2017 | E2: Sep 2017 | F2: Dec 2017 | G2: 44805
B3: Gross income | C3: 27243099 | D3: 55938093 | E3: 85476633 | F3: 116841755 | G3: 76055638
B4: Interest income | C4: 23931177 | D4: 49466361 | E4: 76424541 | F4: 104049102 | G4: 62139977
B5: Less : Interest expense | C5: 15144424 | D5: 31376625 | E5: 47780885 | F5: 64481804 | G5: 40038742
B6: Net interest income | C6: 8786753 | D6: 18089736 | E6: 28643656 | F6: 39567298 | G6: 22101235
B7: Fee and commission income | C7: - | D7: 4859671 | E7: 7496694 | F7: 10510800 | G7: 6447150
B8: Less: Fee and commission expense | C8: - | D8: 777261 | E8: 1178744 | F8: 1586334 | G8: 1411595
B9: Net fee and commission income | C9: - | D9: 4082410 | E9: 6317950 | F9: 8924466 | G9: 5035555
B10: Net gains/(losses) from trading | C10: 789108 | D10: 1271114 | E10: 350857 | F10: 233956 | G10: 2022197
B11: Net gains/(losses) from derecognition of financial assets | C11: - | D11: - | E11: - | F11: - | G11: 106832
B12: Net other operating income | C12: - | D12: - | E12: - | F12: - | G12: 5339482
B13: Total operating income | C13: 11693443 | D13: - | E13: 36517004 | F13: 50773617 | G13: 34605301
B14: Less : Impairment charges and other losses | C14: - | D14: - | E14: - | F14: - | G14: 17052988
B15: Net operating income | C15: 11441564 | D15: 22823634 | E15: 34897960 | F15: 48547703 | G15: 17552313
B16: Less: Expenses | C16: 5009500 | D16: 9937631 | E16: 14939808 | F16: 20374437 | G16: 7985228
B17: Personnel expenses | C17: 2727154 | D17: 5488192 | E17: 8380408 | F17: 11338517 | G17: 5055534
B18: Depreciation and amortisation | C18: 329807 | D18: 690052 | E18: 1044044 | F18: 1416927 | G18: 905454
B19: Other operating expenses | C19: - | D19: - | E19: - | F19: - | G19: 2024240
B20: Operating profit before Taxes on financial services | C20: - | D20: - | E20: - | F20: - | G20: 9567085
B21: Less: Taxes on financial services | C21: - | D21: - | E21: - | F21: - | G21: 907846
B22: Operating profit after Taxes on financial services | C22: - | D22: - | E22: - | F22: - | G22: 8659239
B23: Add/(less): Share of profit/(loss) of associate, net of tax | C23: - | D23: - | E23: - | F23: - | G23: 1220
B24: Profit before income tax | C24: 5306793 | D24: 10609103 | E24: 16406082 | F24: 23280324 | G24: 8660459
B25: Less : Income tax expense / (reversal) | C25: 1493057 | D25: 2954835 | E25: 4632201 | F25: 6653817 | G25: 2377804
B26: Profit for the period | C26: 3813736 | D26: 7654268 | E26: 11773881 | F26: 16626507 | G26: 6282655
B27: Profit attributable to: | C27: - | D27: - | E27: - | F27: -
B28: Equity holders of the Bank | C28: 3819907 | D28: 7657744 | E28: 11769309 | F28: 16605963 | G28: 6095730
B29: Non-controlling interest | C29: -6171 | D29: -3476 | E29: 4572 | F29: 20544 | G29: 186925
B30: Profit for the period | C30: 3813736 | D30: 7654268 | E30: 11773881 | F30: 16626507 | G30: 6282655
B31: Earnings per share | C31: - | D31: - | E31: - | F31: -
B32: Earnings per share | C32: 4.75 | D32: 2.86 | E32: 3.21 | F32: 7.08 | G32: 4.92
